<?xml version="1.0"?>
<robot name="grips" xmlns:xacro="http://www.ros.org/wiki/xacro">
  <macro name="grips_robot" params="name">
    <!-- base link -->
    <link_collision name="${name}base_link" color="black" mesh="${base_mesh}" cog="${base_cog}" mass="${base_mass}" >
      <mesh filename="package://grips_description/meshes/base/base_collision.dae" />
      <base_inertia />
    </link_collision>
    <!-- manifold link -->
    <link_collision name="${name}manifold" color="blue" mesh="${manifold_mesh}" cog="${manifold_cog}" mass="${manifold_mass}" >
      <mesh filename="package://grips_description/meshes/manifold/manifold_collision.dae" />
      <manifold_inertia />
    </link_collision>
    <!-- upper arm link -->
    <link_collision name="${name}upper_arm" color="black" mesh="${upper_arm_mesh}" cog="${upper_arm_cog}" mass="${upper_arm_mass}" >
      <mesh filename="package://grips_description/meshes/upper_arm/upper_arm_collision.dae" />
      <upper_arm_inertia />
    </link_collision>
    <!-- elbow pivot link -->
    <create_link name="${name}elbow_pivot" color="black" mesh="${elbow_pivot_mesh}" cog="${elbow_pivot_cog}" mass="${elbow_pivot_mass}" >
      <elbow_pivot_inertia />
    </create_link>
    <!-- coupling link -->
    <create_link name="${name}coupling" color="black" mesh="${coupling_mesh}" cog="${coupling_cog}" mass="${coupling_mass}" >
      <coupling_inertia />
    </create_link>
    <!-- forearm link -->
    <link_collision name="${name}forearm" color="black" mesh="${forearm_mesh}" cog="${forearm_cog}" mass="${forearm_mass}" >
      <mesh filename="package://grips_description/meshes/forearm/forearm_collision.dae" />
      <forearm_inertia />
    </link_collision>
    <!-- pitch link -->
    <link_collision name="${name}pitch" color="black" mesh="${pitch_mesh}" cog="${pitch_cog}" mass="${pitch_mass}" >
      <mesh filename="package://grips_description/meshes/pitch/pitch_collision.dae" />
      <pitch_inertia />
    </link_collision>
    <!-- yaw link -->
    <link_collision name="${name}yaw" color="black" mesh="${yaw_mesh}" cog="${yaw_cog}" mass="${yaw_mass}" >
      <mesh filename="package://grips_description/meshes/yaw/yaw_collision.dae" />
      <yaw_inertia />
    </link_collision>
    <!-- end effector dummy link -->
    <link name="${name}end_effector" />
    <!-- camera link -->
    <link_collision name="${name}camera" color="black" mesh="${camera_mesh}" cog="${camera_cog}" mass="${camera_mass}" >
      <mesh filename="package://grips_description/meshes/camera/camera_collision.dae" />
      <camera_inertia />
    </link_collision>
          
    <!-- Joints -->
    <joint name="${name}SA" type="revolute">
      <child link="${name}manifold" />
      <parent link="${name}base_link" />
      <axis xyz="0 0 1" />
      <origin xyz="0 0 15.24e-3" rpy="0 0 0" />
      <limit lower="${-pi/2}" upper="${pi/2}" effort="${max_effort}" velocity="${max_velocity}" />
      <dynamics damping="${SA_damping}"/>
    </joint>
    <joint name="${name}SE" type="revolute">
      <child link="${name}upper_arm" />
      <parent link="${name}manifold" />
      <axis xyz="1 0 0" />
      <origin xyz="0 0 0.33812" rpy="0 0 0" />
      <limit lower="${-pi/2}" upper="${pi/6}" effort="${max_effort}" velocity="${max_velocity}" />
      <dynamics damping="${SE_damping}" friction="10"/>
    </joint>
    <joint name="${name}linkage_tr" type="revolute">
      <child link="${name}forearm" />
      <parent link="${name}upper_arm" />
      <axis xyz="1 0 0" />
      <origin xyz="0 -9.82e-3 0.52167" rpy="0 0 0" />
      <limit lower="-1.28" upper="${pi/3}" effort="${max_effort}" velocity="${max_velocity}" />
      <dynamics damping="10"/>
    </joint>
    <joint name="${name}WP" type="revolute">
      <child link="${name}pitch" />
      <parent link="${name}forearm" />
      <axis xyz="1 0 0" />
      <origin xyz="0 0.26109 7.5e-3" rpy="0 0 0" />
      <limit lower="-0.581" upper="1.1" effort="${max_effort}" velocity="${max_velocity}" />
      <dynamics damping="${WP_damping}"/>
    </joint>
    <joint name="${name}WY" type="revolute">
      <child link="${name}yaw" />
      <parent link="${name}pitch" />
      <axis xyz="0 0 1" />
      <origin xyz="0 0.13322 0" rpy="0 0 0" />
      <limit lower="-1.01" upper="0.675" effort="${max_effort}" velocity="${max_velocity}" />
      <dynamics damping="${WY_damping}"/>
    </joint>
    <joint name="${name}WR" type="continuous">
      <child link="${name}end_effector" />
      <parent link="${name}yaw" />
      <axis xyz="0 1 0" />
      <origin xyz="-0.787e-3 0.190892 0.051331" rpy="0 0 0" />
      <limit effort="${max_effort}" velocity="200" />
      <dynamics damping="${WR_damping}"/>
    </joint>
    <joint name="${name}camera_joint" type="fixed">
      <child link="${name}camera"/>
      <parent link="${name}yaw"/>
      <axis xyz="0 1 0" />
      <origin xyz="0 ${0.190892/2} 0.25" rpy="0 ${pi/6} ${pi/2}"/>    
    </joint>
    
    <!-- four-bar linkage -->
    <joint name="${name}linkage_tl" type="continuous">
      <child link="${name}coupling" />
      <parent link="${name}forearm" />
      <axis xyz="1 0 0" />
      <origin xyz="0 -0.123444 0.029845" rpy="0.019320795 0 0" />
      <limit effort="${max_effort}" velocity="${max_velocity}" />
      <dynamics damping="${linkage_damping}" friction="${linkage_friction}"/>
    </joint>
    <joint name="${name}linkage_bl" type="continuous">
      <child link="${name}elbow_pivot" />
      <parent link="${name}coupling" />
      <axis xyz="1 0 0" />
      <origin xyz="0 0 -0.5207" rpy="-0.24521876 0 0" />
      <limit effort="${max_effort}" velocity="${max_velocity}" />
      <dynamics damping="${linkage_damping}" friction="${linkage_friction}"/>
    </joint>

    <!-- Transmissions -->
    <simple_transmission joint="${name}SA" />
    <simple_transmission joint="${name}SE" />
    <simple_transmission joint="${name}WP" />
    <simple_transmission joint="${name}WY" />
    <simple_transmission joint="${name}WR" />
    <simple_transmission joint="${name}linkage_tr" />
    <simple_transmission joint="${name}linkage_tl" />
    <simple_transmission joint="${name}linkage_bl" />
    
    <gazebo reference="${name}base_link">
      <material>Telerobcar/MetalSeamed</material>
      <selfCollide>false</selfCollide>
    </gazebo>
    <gazebo reference="${name}manifold">
      <material>Telerobcar/MetalSeamed</material>
      <selfCollide>false</selfCollide>
    </gazebo>
    <gazebo reference="${name}upper_arm">
      <material>Telerobcar/MetalSeamed</material>
      <selfCollide>true</selfCollide>
    </gazebo>
    <gazebo reference="${name}elbow_pivot">
      <material>Telerobcar/MetalSeamed</material>
      <selfCollide>false</selfCollide>
    </gazebo>
    <gazebo reference="${name}coupling">
      <material>Telerobcar/MetalSeamed</material>
      <selfCollide>false</selfCollide>
    </gazebo>
    <gazebo reference="${name}forearm">
      <material>Telerobcar/MetalSeamed</material>
      <selfCollide>true</selfCollide>
    </gazebo>
    <gazebo reference="${name}pitch">
      <material>Telerobcar/MetalSeamed</material>
      <selfCollide>true</selfCollide>
    </gazebo>
    <gazebo reference="${name}yaw">
      <material>Telerobcar/MetalSeamed</material>
      <selfCollide>true</selfCollide>
    </gazebo>
    <gazebo reference="${name}end_effector">
      <selfCollide>true</selfCollide>
    </gazebo>
    <!-- camera -->	
    <gazebo reference="${name}camera">
      <material>Gazebo/FlatBlack</material>
      <selfCollide>true</selfCollide>
      <sensor type="camera" name="${name}camera">
        <update_rate>30.0</update_rate>
        <camera name="${name}camera">
          <horizontal_fov>1.3962634</horizontal_fov>
          <image>
            <width>800</width>
            <height>800</height>
            <format>R8G8B8</format>
          </image>
          <clip>
            <near>0.02</near>
            <far>300</far>
          </clip>
        </camera>
        <plugin name="camera_controller" filename="libgazebo_ros_camera.so">
          <alwaysOn>true</alwaysOn>
          <updateRate>0.0</updateRate>
          <cameraName>${name}camera</cameraName>
          <imageTopicName>image_raw</imageTopicName>
          <cameraInfoTopicName>camera_info</cameraInfoTopicName>
          <frameName>${name}camera</frameName>
          <hackBaseline>0.07</hackBaseline>
          <distortionK1>0.0</distortionK1>
          <distortionK2>0.0</distortionK2>
          <distortionK3>0.0</distortionK3>
          <distortionT1>0.0</distortionT1>
          <distortionT2>0.0</distortionT2>
        </plugin>
      </sensor>
    </gazebo>
  </macro>  
</robot>
