<?xml version="1.0"?>
<robot name="grips" xmlns:xacro="http://www.ros.org/wiki/xacro">
  <macro name="grips_robot" params="name">
    <!-- base link -->
    <link_collision name="${name}base_link" color="black" mesh="${base_mesh}" cog="${base_cog}" mass="${base_mass}" >
      <mesh filename="package://grips_description/meshes/collision/base.dae" />
      <base_inertia />
    </link_collision>
    <!-- manifold link -->
    <link_collision name="${name}manifold" color="blue" mesh="${manifold_mesh}" cog="${manifold_cog}" mass="${manifold_mass}" >
      <mesh filename="package://grips_description/meshes/collision/manifold.dae" />
      <manifold_inertia />
    </link_collision>
    <!-- upper arm link -->
    <link_collision name="${name}upper_arm" color="black" mesh="${upper_arm_mesh}" cog="${upper_arm_cog}" mass="${upper_arm_mass}" >
      <mesh filename="package://grips_description/meshes/collision/upper_arm.dae" />
      <upper_arm_inertia />
    </link_collision>
    <!-- forearm link -->
    <link_collision name="${name}forearm" color="black" mesh="${forearm_mesh}" cog="${forearm_cog}" mass="${forearm_mass}" >
      <mesh filename="package://grips_description/meshes/collision/forearm.dae" />
      <forearm_inertia />
    </link_collision>
    <!-- pitch link -->
    <link_collision name="${name}pitch" color="black" mesh="${pitch_mesh}" cog="${pitch_cog}" mass="${pitch_mass}" >
      <mesh filename="package://grips_description/meshes/collision/pitch.dae" />
      <pitch_inertia />
    </link_collision>
    <!-- yaw link -->
    <link_collision name="${name}yaw" color="black" mesh="${yaw_mesh}" cog="${yaw_cog}" mass="${yaw_mass}" >
      <mesh filename="package://grips_description/meshes/collision/yaw.dae" />
      <yaw_inertia />
    </link_collision>
    <!-- end effector dummy link -->
    <link name="${name}end_effector" />
          
    <!-- Joints -->
    <joint name="${name}SA" type="revolute">
      <child link="${name}manifold" />
      <parent link="${name}base_link" />
      <axis xyz="0 0 1" />
      <origin xyz="0 0 15.24e-3" rpy="0 0 0" />
      <limit lower="${-pi/2}" upper="${pi/2}" effort="${max_effort}" velocity="${80*pi/180}" />
      <dynamics damping="${SA_damping}"/>
    </joint>
    <joint name="${name}SE" type="revolute">
      <child link="${name}upper_arm" />
      <parent link="${name}manifold" />
      <axis xyz="1 0 0" />
      <origin xyz="0 0 0.33812" rpy="0 0 0" />
      <limit lower="${-pi/2}" upper="${pi/6}" effort="${max_effort}" velocity="${65*pi/180}" />
      <dynamics damping="${SE_damping}" friction="10"/>
    </joint>
    <joint name="${name}linkage_tr" type="revolute">
      <child link="${name}forearm" />
      <parent link="${name}upper_arm" />
      <axis xyz="1 0 0" />
      <origin xyz="0 -9.82e-3 0.52167" rpy="0 0 0" />
      <limit lower="-1.28" upper="${pi/3}" effort="${max_effort}" velocity="${50*pi/180}" />
      <dynamics damping="10"/>
    </joint>
    <joint name="${name}WP" type="revolute">
      <child link="${name}pitch" />
      <parent link="${name}forearm" />
      <axis xyz="1 0 0" />
      <origin xyz="0 0.26109 7.5e-3" rpy="0 0 0" />
      <limit lower="-0.581" upper="1.1" effort="${max_effort}" velocity="${100*pi/180}" />
      <dynamics damping="${WP_damping}"/>
    </joint>
    <joint name="${name}WY" type="revolute">
      <child link="${name}yaw" />
      <parent link="${name}pitch" />
      <axis xyz="0 0 1" />
      <origin xyz="0 0.13322 0" rpy="0 0 0" />
      <limit lower="-1.01" upper="0.675" effort="${max_effort}" velocity="${115*pi/180}" />
      <dynamics damping="${WY_damping}"/>
    </joint>
    <joint name="${name}WR" type="continuous">
      <child link="${name}end_effector" />
      <parent link="${name}yaw" />
      <axis xyz="0 1 0" />
      <origin xyz="-0.787e-3 0.190892 0.051331" rpy="0 0 0" />
      <limit effort="${max_effort}" velocity="${200*pi/180}" />
      <dynamics damping="${WR_damping}"/>
    </joint>

    <!-- Transmissions -->
    <simple_transmission joint="${name}SA" />
    <simple_transmission joint="${name}SE" />
    <simple_transmission joint="${name}WP" />
    <simple_transmission joint="${name}WY" />
    <simple_transmission joint="${name}WR" />
    <simple_transmission joint="${name}linkage_tr" />
    
    <gazebo reference="${name}base_link">
      <material>Telerobcar/MetalSeamed</material>
      <selfCollide>false</selfCollide>
    </gazebo>
    <gazebo reference="${name}manifold">
      <material>Telerobcar/MetalSeamed</material>
      <selfCollide>false</selfCollide>
    </gazebo>
    <gazebo reference="${name}upper_arm">
      <material>Telerobcar/MetalSeamed</material>
      <selfCollide>false</selfCollide>
    </gazebo>
    <gazebo reference="${name}forearm">
      <material>Telerobcar/MetalSeamed</material>
      <selfCollide>false</selfCollide>
    </gazebo>
    <gazebo reference="${name}pitch">
      <material>Telerobcar/MetalSeamed</material>
      <selfCollide>false</selfCollide>
    </gazebo>
    <gazebo reference="${name}yaw">
      <material>Telerobcar/MetalSeamed</material>
      <selfCollide>false</selfCollide>
    </gazebo>
    <gazebo reference="${name}end_effector">
      <selfCollide>false</selfCollide>
    </gazebo>
  </macro>  
</robot>
