<?xml version="1.0" ?>
<!-- =================================================================================== -->
<!-- |    This document was autogenerated by xacro from /home/fsuarez6/catkin_ws/src/grips/grips_description/robots/bimanual.xacro | -->
<!-- |    EDITING THIS FILE BY HAND IS NOT RECOMMENDED                                 | -->
<!-- =================================================================================== -->
<robot name="grips" xmlns:xacro="http://www.ros.org/wiki/xacro">
  <!-- Import common macros-->
  <!-- Import materials for rviz-->
  <material name="black">
    <color rgba="0.0 0.0 0.0 1.0"/>
  </material>
  <material name="blue">
    <color rgba="0.0 0.0 0.8 1.0"/>
  </material>
  <material name="green">
    <color rgba="0.0 0.8 0.0 1.0"/>
  </material>
  <material name="grey">
    <color rgba="0.2 0.2 0.2 1.0"/>
  </material>
  <material name="orange">
    <color rgba="1.0 0.423529411765 0.0392156862745 1.0"/>
  </material>
  <material name="brown">
    <color rgba="0.870588235294 0.811764705882 0.764705882353 1.0"/>
  </material>
  <material name="red">
    <color rgba="0.8 0.0 0.0 1.0"/>
  </material>
  <material name="white">
    <color rgba="1.0 1.0 1.0 1.0"/>
  </material>
  <material name="metal_seamed">
    <color rgba="0.4627450980392157 0.4666666666666667 0.4509803921568628 1.0"/>
  </material>
  <!-- Import robot without gripper -->
  <!-- Import simple gripper -->
  <!-- Create the grips robots -->
  <link name="left_base_link">
    <visual>
      <geometry>
        <mesh filename="package://grips_description/meshes/base/base.dae"/>
      </geometry>
      <material name="black"/>
    </visual>
    <collision>
      <geometry>
        <mesh filename="package://grips_description/meshes/base/base_collision.dae"/>
      </geometry>
    </collision>
    <inertial>
      <origin rpy="0 0 0" xyz="0 0 7e-3"/>
      <mass value="1.208"/>
      <inertia ixx="0.003" ixy="0.0" ixz="0.0" iyy="0.003" iyz="0.0" izz="0.006"/>
    </inertial>
  </link>
  <link name="left_manifold">
    <visual>
      <geometry>
        <mesh filename="package://grips_description/meshes/manifold/manifold.dae"/>
      </geometry>
      <material name="blue"/>
    </visual>
    <collision>
      <geometry>
        <mesh filename="package://grips_description/meshes/manifold/manifold_collision.dae"/>
      </geometry>
    </collision>
    <inertial>
      <origin rpy="0 0 0" xyz="0 2e-3 0.21"/>
      <mass value="41.111"/>
      <inertia ixx="0.549" ixy="-9.556e-5" ixz="-5.871e-5" iyy="0.855" iyz="2e-3" izz="0.605"/>
    </inertial>
  </link>
  <link name="left_upper_arm">
    <visual>
      <geometry>
        <mesh filename="package://grips_description/meshes/upper_arm/upper_arm.dae"/>
      </geometry>
      <material name="black"/>
    </visual>
    <collision>
      <geometry>
        <mesh filename="package://grips_description/meshes/upper_arm/upper_arm_collision.dae"/>
      </geometry>
    </collision>
    <inertial>
      <origin rpy="0 0 0" xyz="0 5e-3 0.227"/>
      <mass value="3.592"/>
      <inertia ixx="0.103" ixy="0" ixz="0" iyy="0.106" iyz="0.004" izz="0.013"/>
    </inertial>
  </link>
  <link name="left_elbow_pivot">
    <visual>
      <geometry>
        <mesh filename="package://grips_description/meshes/linkage/elbow_pivot.dae"/>
      </geometry>
      <material name="black"/>
    </visual>
    <collision>
      <geometry>
        <mesh filename="package://grips_description/meshes/linkage/elbow_pivot.dae"/>
      </geometry>
    </collision>
    <inertial>
      <origin rpy="0 0 0" xyz="-3.6e-10 80.686e-3 -6.33e-5"/>
      <mass value="0.72"/>
      <inertia ixx="0.002" ixy="-3.231e-27" ixz="0" iyy="3.397e-4" iyz="-1.919e-5" izz="0.002"/>
    </inertial>
  </link>
  <link name="left_coupling">
    <visual>
      <geometry>
        <mesh filename="package://grips_description/meshes/linkage/coupling.dae"/>
      </geometry>
      <material name="black"/>
    </visual>
    <collision>
      <geometry>
        <mesh filename="package://grips_description/meshes/linkage/coupling.dae"/>
      </geometry>
    </collision>
    <inertial>
      <origin rpy="0 0 0" xyz="0 0 -0.26035"/>
      <mass value="0.446"/>
      <inertia ixx="0.011" ixy="-3.231e-27" ixz="0" iyy="0.011" iyz="0" izz="2.102e-5"/>
    </inertial>
  </link>
  <link name="left_forearm">
    <visual>
      <geometry>
        <mesh filename="package://grips_description/meshes/forearm/forearm.dae"/>
      </geometry>
      <material name="black"/>
    </visual>
    <collision>
      <geometry>
        <mesh filename="package://grips_description/meshes/forearm/forearm_collision.dae"/>
      </geometry>
    </collision>
    <inertial>
      <origin rpy="0 0 0" xyz="0 0.155337 0.012119"/>
      <mass value="4.935"/>
      <inertia ixx="0.073" ixy="0" ixz="0" iyy="0.009" iyz="0.004" izz="0.073"/>
    </inertial>
  </link>
  <link name="left_pitch">
    <visual>
      <geometry>
        <mesh filename="package://grips_description/meshes/pitch/pitch.dae"/>
      </geometry>
      <material name="black"/>
    </visual>
    <collision>
      <geometry>
        <mesh filename="package://grips_description/meshes/pitch/pitch_collision.dae"/>
      </geometry>
    </collision>
    <inertial>
      <origin rpy="0 0 0" xyz="0 0.065 0"/>
      <mass value="0.679"/>
      <inertia ixx="0.003" ixy="0" ixz="0" iyy="0.002" iyz="0.004" izz="0.002"/>
    </inertial>
  </link>
  <link name="left_yaw">
    <visual>
      <geometry>
        <mesh filename="package://grips_description/meshes/yaw/yaw.dae"/>
      </geometry>
      <material name="black"/>
    </visual>
    <collision>
      <geometry>
        <mesh filename="package://grips_description/meshes/yaw/yaw_collision.dae"/>
      </geometry>
    </collision>
    <inertial>
      <origin rpy="0 0 0" xyz="-1e-3 95.791e-3 18.273e-3"/>
      <mass value="4.689"/>
      <inertia ixx="0.027" ixy="1.597e-4" ixz="-2.174e-4" iyy="0.009" iyz="-0.003" izz="0.026"/>
    </inertial>
  </link>
  <link name="left_end_effector"/>
  <link name="left_camera">
    <visual>
      <geometry>
        <mesh filename="package://grips_description/meshes/camera/camera.dae"/>
      </geometry>
      <material name="black"/>
    </visual>
    <collision>
      <geometry>
        <mesh filename="package://grips_description/meshes/camera/camera_collision.dae"/>
      </geometry>
    </collision>
    <inertial>
      <origin rpy="0 0 0" xyz="0.077 0.007 0.002"/>
      <mass value="0.869"/>
      <inertia ixx="0.001" ixy="-1.561e-4" ixz="-5.859e-5" iyy="0.002" iyz="3.295e-5" izz="0.002"/>
    </inertial>
  </link>
  <joint name="left_SA" type="revolute">
    <child link="left_manifold"/>
    <parent link="left_base_link"/>
    <axis xyz="0 0 1"/>
    <origin rpy="0 0 0" xyz="0 0 15.24e-3"/>
    <limit effort="200" lower="-1.57079632679" upper="1.57079632679" velocity="15"/>
    <dynamics damping="5"/>
  </joint>
  <joint name="left_SE" type="revolute">
    <child link="left_upper_arm"/>
    <parent link="left_manifold"/>
    <axis xyz="1 0 0"/>
    <origin rpy="0 0 0" xyz="0 0 0.33812"/>
    <limit effort="200" lower="-1.57079632679" upper="0.523598775598" velocity="15"/>
    <dynamics damping="5" friction="10"/>
  </joint>
  <joint name="left_linkage_tr" type="revolute">
    <child link="left_forearm"/>
    <parent link="left_upper_arm"/>
    <axis xyz="1 0 0"/>
    <origin rpy="0 0 0" xyz="0 -9.82e-3 0.52167"/>
    <limit effort="200" lower="-1.28" upper="1.0471975512" velocity="15"/>
    <dynamics damping="10"/>
  </joint>
  <joint name="left_WP" type="revolute">
    <child link="left_pitch"/>
    <parent link="left_forearm"/>
    <axis xyz="1 0 0"/>
    <origin rpy="0 0 0" xyz="0 0.26109 7.5e-3"/>
    <limit effort="200" lower="-1.1" upper="0.581" velocity="15"/>
    <dynamics damping="5"/>
  </joint>
  <joint name="left_WY" type="revolute">
    <child link="left_yaw"/>
    <parent link="left_pitch"/>
    <axis xyz="0 0 1"/>
    <origin rpy="0 0 0" xyz="0 0.13322 0"/>
    <limit effort="200" lower="-1.01" upper="0.675" velocity="15"/>
    <dynamics damping="5"/>
  </joint>
  <joint name="left_WR" type="continuous">
    <child link="left_end_effector"/>
    <parent link="left_yaw"/>
    <axis xyz="0 1 0"/>
    <origin rpy="0 0 0" xyz="-0.787e-3 0.190892 0.051331"/>
    <limit effort="200" velocity="200"/>
    <dynamics damping="0.5"/>
  </joint>
  <joint name="left_camera_joint" type="fixed">
    <child link="left_camera"/>
    <parent link="left_yaw"/>
    <axis xyz="0 1 0"/>
    <origin rpy="0 0.523598775598 1.57079632679" xyz="0 0.095446 0.25"/>
  </joint>
  <joint name="left_linkage_tl" type="continuous">
    <child link="left_coupling"/>
    <parent link="left_forearm"/>
    <axis xyz="1 0 0"/>
    <origin rpy="0.019320795 0 0" xyz="0 -0.123444 0.029845"/>
    <limit effort="200" velocity="15"/>
    <dynamics damping="0.5" friction="0.5"/>
  </joint>
  <joint name="left_linkage_bl" type="continuous">
    <child link="left_elbow_pivot"/>
    <parent link="left_coupling"/>
    <axis xyz="1 0 0"/>
    <origin rpy="-0.24521876 0 0" xyz="0 0 -0.5207"/>
    <limit effort="200" velocity="15"/>
    <dynamics damping="0.5" friction="0.5"/>
  </joint>
  <transmission name="left_SA_tran">
    <type>transmission_interface/SimpleTransmission</type>
    <joint name="left_SA"/>
    <actuator name="left_SA_motor">
      <hardwareInterface>EffortJointInterface</hardwareInterface>
      <mechanicalReduction>1</mechanicalReduction>
    </actuator>
  </transmission>
  <transmission name="left_SE_tran">
    <type>transmission_interface/SimpleTransmission</type>
    <joint name="left_SE"/>
    <actuator name="left_SE_motor">
      <hardwareInterface>EffortJointInterface</hardwareInterface>
      <mechanicalReduction>1</mechanicalReduction>
    </actuator>
  </transmission>
  <transmission name="left_WP_tran">
    <type>transmission_interface/SimpleTransmission</type>
    <joint name="left_WP"/>
    <actuator name="left_WP_motor">
      <hardwareInterface>EffortJointInterface</hardwareInterface>
      <mechanicalReduction>1</mechanicalReduction>
    </actuator>
  </transmission>
  <transmission name="left_WY_tran">
    <type>transmission_interface/SimpleTransmission</type>
    <joint name="left_WY"/>
    <actuator name="left_WY_motor">
      <hardwareInterface>EffortJointInterface</hardwareInterface>
      <mechanicalReduction>1</mechanicalReduction>
    </actuator>
  </transmission>
  <transmission name="left_WR_tran">
    <type>transmission_interface/SimpleTransmission</type>
    <joint name="left_WR"/>
    <actuator name="left_WR_motor">
      <hardwareInterface>EffortJointInterface</hardwareInterface>
      <mechanicalReduction>1</mechanicalReduction>
    </actuator>
  </transmission>
  <transmission name="left_linkage_tr_tran">
    <type>transmission_interface/SimpleTransmission</type>
    <joint name="left_linkage_tr"/>
    <actuator name="left_linkage_tr_motor">
      <hardwareInterface>EffortJointInterface</hardwareInterface>
      <mechanicalReduction>1</mechanicalReduction>
    </actuator>
  </transmission>
  <transmission name="left_linkage_tl_tran">
    <type>transmission_interface/SimpleTransmission</type>
    <joint name="left_linkage_tl"/>
    <actuator name="left_linkage_tl_motor">
      <hardwareInterface>EffortJointInterface</hardwareInterface>
      <mechanicalReduction>1</mechanicalReduction>
    </actuator>
  </transmission>
  <transmission name="left_linkage_bl_tran">
    <type>transmission_interface/SimpleTransmission</type>
    <joint name="left_linkage_bl"/>
    <actuator name="left_linkage_bl_motor">
      <hardwareInterface>EffortJointInterface</hardwareInterface>
      <mechanicalReduction>1</mechanicalReduction>
    </actuator>
  </transmission>
  <gazebo reference="left_base_link">
    <material>Telerobcar/MetalSeamed</material>
    <selfCollide>false</selfCollide>
  </gazebo>
  <gazebo reference="left_manifold">
    <material>Telerobcar/MetalSeamed</material>
    <selfCollide>false</selfCollide>
  </gazebo>
  <gazebo reference="left_upper_arm">
    <material>Telerobcar/MetalSeamed</material>
    <selfCollide>false</selfCollide>
  </gazebo>
  <gazebo reference="left_elbow_pivot">
    <material>Telerobcar/MetalSeamed</material>
    <selfCollide>false</selfCollide>
  </gazebo>
  <gazebo reference="left_coupling">
    <material>Telerobcar/MetalSeamed</material>
    <selfCollide>false</selfCollide>
  </gazebo>
  <gazebo reference="left_forearm">
    <material>Telerobcar/MetalSeamed</material>
    <selfCollide>false</selfCollide>
  </gazebo>
  <gazebo reference="left_pitch">
    <material>Telerobcar/MetalSeamed</material>
    <selfCollide>false</selfCollide>
  </gazebo>
  <gazebo reference="left_yaw">
    <material>Telerobcar/MetalSeamed</material>
    <selfCollide>false</selfCollide>
  </gazebo>
  <gazebo reference="left_camera">
    <material>Gazebo/FlatBlack</material>
    <selfCollide>false</selfCollide>
    <sensor name="left_camera" type="camera">
      <update_rate>30.0</update_rate>
      <camera name="left_camera">
        <horizontal_fov>1.3962634</horizontal_fov>
        <image>
          <width>800</width>
          <height>800</height>
          <format>R8G8B8</format>
        </image>
        <clip>
          <near>0.02</near>
          <far>300</far>
        </clip>
      </camera>
      <plugin filename="libgazebo_ros_camera.so" name="camera_controller">
        <alwaysOn>true</alwaysOn>
        <updateRate>0.0</updateRate>
        <cameraName>left_camera</cameraName>
        <imageTopicName>image_raw</imageTopicName>
        <cameraInfoTopicName>camera_info</cameraInfoTopicName>
        <frameName>left_camera</frameName>
        <hackBaseline>0.07</hackBaseline>
        <distortionK1>0.0</distortionK1>
        <distortionK2>0.0</distortionK2>
        <distortionK3>0.0</distortionK3>
        <distortionT1>0.0</distortionT1>
        <distortionT2>0.0</distortionT2>
      </plugin>
    </sensor>
  </gazebo>
  <link name="right_base_link">
    <visual>
      <geometry>
        <mesh filename="package://grips_description/meshes/base/base.dae"/>
      </geometry>
      <material name="black"/>
    </visual>
    <collision>
      <geometry>
        <mesh filename="package://grips_description/meshes/base/base_collision.dae"/>
      </geometry>
    </collision>
    <inertial>
      <origin rpy="0 0 0" xyz="0 0 7e-3"/>
      <mass value="1.208"/>
      <inertia ixx="0.003" ixy="0.0" ixz="0.0" iyy="0.003" iyz="0.0" izz="0.006"/>
    </inertial>
  </link>
  <link name="right_manifold">
    <visual>
      <geometry>
        <mesh filename="package://grips_description/meshes/manifold/manifold.dae"/>
      </geometry>
      <material name="blue"/>
    </visual>
    <collision>
      <geometry>
        <mesh filename="package://grips_description/meshes/manifold/manifold_collision.dae"/>
      </geometry>
    </collision>
    <inertial>
      <origin rpy="0 0 0" xyz="0 2e-3 0.21"/>
      <mass value="41.111"/>
      <inertia ixx="0.549" ixy="-9.556e-5" ixz="-5.871e-5" iyy="0.855" iyz="2e-3" izz="0.605"/>
    </inertial>
  </link>
  <link name="right_upper_arm">
    <visual>
      <geometry>
        <mesh filename="package://grips_description/meshes/upper_arm/upper_arm.dae"/>
      </geometry>
      <material name="black"/>
    </visual>
    <collision>
      <geometry>
        <mesh filename="package://grips_description/meshes/upper_arm/upper_arm_collision.dae"/>
      </geometry>
    </collision>
    <inertial>
      <origin rpy="0 0 0" xyz="0 5e-3 0.227"/>
      <mass value="3.592"/>
      <inertia ixx="0.103" ixy="0" ixz="0" iyy="0.106" iyz="0.004" izz="0.013"/>
    </inertial>
  </link>
  <link name="right_elbow_pivot">
    <visual>
      <geometry>
        <mesh filename="package://grips_description/meshes/linkage/elbow_pivot.dae"/>
      </geometry>
      <material name="black"/>
    </visual>
    <collision>
      <geometry>
        <mesh filename="package://grips_description/meshes/linkage/elbow_pivot.dae"/>
      </geometry>
    </collision>
    <inertial>
      <origin rpy="0 0 0" xyz="-3.6e-10 80.686e-3 -6.33e-5"/>
      <mass value="0.72"/>
      <inertia ixx="0.002" ixy="-3.231e-27" ixz="0" iyy="3.397e-4" iyz="-1.919e-5" izz="0.002"/>
    </inertial>
  </link>
  <link name="right_coupling">
    <visual>
      <geometry>
        <mesh filename="package://grips_description/meshes/linkage/coupling.dae"/>
      </geometry>
      <material name="black"/>
    </visual>
    <collision>
      <geometry>
        <mesh filename="package://grips_description/meshes/linkage/coupling.dae"/>
      </geometry>
    </collision>
    <inertial>
      <origin rpy="0 0 0" xyz="0 0 -0.26035"/>
      <mass value="0.446"/>
      <inertia ixx="0.011" ixy="-3.231e-27" ixz="0" iyy="0.011" iyz="0" izz="2.102e-5"/>
    </inertial>
  </link>
  <link name="right_forearm">
    <visual>
      <geometry>
        <mesh filename="package://grips_description/meshes/forearm/forearm.dae"/>
      </geometry>
      <material name="black"/>
    </visual>
    <collision>
      <geometry>
        <mesh filename="package://grips_description/meshes/forearm/forearm_collision.dae"/>
      </geometry>
    </collision>
    <inertial>
      <origin rpy="0 0 0" xyz="0 0.155337 0.012119"/>
      <mass value="4.935"/>
      <inertia ixx="0.073" ixy="0" ixz="0" iyy="0.009" iyz="0.004" izz="0.073"/>
    </inertial>
  </link>
  <link name="right_pitch">
    <visual>
      <geometry>
        <mesh filename="package://grips_description/meshes/pitch/pitch.dae"/>
      </geometry>
      <material name="black"/>
    </visual>
    <collision>
      <geometry>
        <mesh filename="package://grips_description/meshes/pitch/pitch_collision.dae"/>
      </geometry>
    </collision>
    <inertial>
      <origin rpy="0 0 0" xyz="0 0.065 0"/>
      <mass value="0.679"/>
      <inertia ixx="0.003" ixy="0" ixz="0" iyy="0.002" iyz="0.004" izz="0.002"/>
    </inertial>
  </link>
  <link name="right_yaw">
    <visual>
      <geometry>
        <mesh filename="package://grips_description/meshes/yaw/yaw.dae"/>
      </geometry>
      <material name="black"/>
    </visual>
    <collision>
      <geometry>
        <mesh filename="package://grips_description/meshes/yaw/yaw_collision.dae"/>
      </geometry>
    </collision>
    <inertial>
      <origin rpy="0 0 0" xyz="-1e-3 95.791e-3 18.273e-3"/>
      <mass value="4.689"/>
      <inertia ixx="0.027" ixy="1.597e-4" ixz="-2.174e-4" iyy="0.009" iyz="-0.003" izz="0.026"/>
    </inertial>
  </link>
  <link name="right_end_effector"/>
  <link name="right_camera">
    <visual>
      <geometry>
        <mesh filename="package://grips_description/meshes/camera/camera.dae"/>
      </geometry>
      <material name="black"/>
    </visual>
    <collision>
      <geometry>
        <mesh filename="package://grips_description/meshes/camera/camera_collision.dae"/>
      </geometry>
    </collision>
    <inertial>
      <origin rpy="0 0 0" xyz="0.077 0.007 0.002"/>
      <mass value="0.869"/>
      <inertia ixx="0.001" ixy="-1.561e-4" ixz="-5.859e-5" iyy="0.002" iyz="3.295e-5" izz="0.002"/>
    </inertial>
  </link>
  <joint name="right_SA" type="revolute">
    <child link="right_manifold"/>
    <parent link="right_base_link"/>
    <axis xyz="0 0 1"/>
    <origin rpy="0 0 0" xyz="0 0 15.24e-3"/>
    <limit effort="200" lower="-1.57079632679" upper="1.57079632679" velocity="15"/>
    <dynamics damping="5"/>
  </joint>
  <joint name="right_SE" type="revolute">
    <child link="right_upper_arm"/>
    <parent link="right_manifold"/>
    <axis xyz="1 0 0"/>
    <origin rpy="0 0 0" xyz="0 0 0.33812"/>
    <limit effort="200" lower="-1.57079632679" upper="0.523598775598" velocity="15"/>
    <dynamics damping="5" friction="10"/>
  </joint>
  <joint name="right_linkage_tr" type="revolute">
    <child link="right_forearm"/>
    <parent link="right_upper_arm"/>
    <axis xyz="1 0 0"/>
    <origin rpy="0 0 0" xyz="0 -9.82e-3 0.52167"/>
    <limit effort="200" lower="-1.28" upper="1.0471975512" velocity="15"/>
    <dynamics damping="10"/>
  </joint>
  <joint name="right_WP" type="revolute">
    <child link="right_pitch"/>
    <parent link="right_forearm"/>
    <axis xyz="1 0 0"/>
    <origin rpy="0 0 0" xyz="0 0.26109 7.5e-3"/>
    <limit effort="200" lower="-1.1" upper="0.581" velocity="15"/>
    <dynamics damping="5"/>
  </joint>
  <joint name="right_WY" type="revolute">
    <child link="right_yaw"/>
    <parent link="right_pitch"/>
    <axis xyz="0 0 1"/>
    <origin rpy="0 0 0" xyz="0 0.13322 0"/>
    <limit effort="200" lower="-1.01" upper="0.675" velocity="15"/>
    <dynamics damping="5"/>
  </joint>
  <joint name="right_WR" type="continuous">
    <child link="right_end_effector"/>
    <parent link="right_yaw"/>
    <axis xyz="0 1 0"/>
    <origin rpy="0 0 0" xyz="-0.787e-3 0.190892 0.051331"/>
    <limit effort="200" velocity="200"/>
    <dynamics damping="0.5"/>
  </joint>
  <joint name="right_camera_joint" type="fixed">
    <child link="right_camera"/>
    <parent link="right_yaw"/>
    <axis xyz="0 1 0"/>
    <origin rpy="0 0.523598775598 1.57079632679" xyz="0 0.095446 0.25"/>
  </joint>
  <joint name="right_linkage_tl" type="continuous">
    <child link="right_coupling"/>
    <parent link="right_forearm"/>
    <axis xyz="1 0 0"/>
    <origin rpy="0.019320795 0 0" xyz="0 -0.123444 0.029845"/>
    <limit effort="200" velocity="15"/>
    <dynamics damping="0.5" friction="0.5"/>
  </joint>
  <joint name="right_linkage_bl" type="continuous">
    <child link="right_elbow_pivot"/>
    <parent link="right_coupling"/>
    <axis xyz="1 0 0"/>
    <origin rpy="-0.24521876 0 0" xyz="0 0 -0.5207"/>
    <limit effort="200" velocity="15"/>
    <dynamics damping="0.5" friction="0.5"/>
  </joint>
  <transmission name="right_SA_tran">
    <type>transmission_interface/SimpleTransmission</type>
    <joint name="right_SA"/>
    <actuator name="right_SA_motor">
      <hardwareInterface>EffortJointInterface</hardwareInterface>
      <mechanicalReduction>1</mechanicalReduction>
    </actuator>
  </transmission>
  <transmission name="right_SE_tran">
    <type>transmission_interface/SimpleTransmission</type>
    <joint name="right_SE"/>
    <actuator name="right_SE_motor">
      <hardwareInterface>EffortJointInterface</hardwareInterface>
      <mechanicalReduction>1</mechanicalReduction>
    </actuator>
  </transmission>
  <transmission name="right_WP_tran">
    <type>transmission_interface/SimpleTransmission</type>
    <joint name="right_WP"/>
    <actuator name="right_WP_motor">
      <hardwareInterface>EffortJointInterface</hardwareInterface>
      <mechanicalReduction>1</mechanicalReduction>
    </actuator>
  </transmission>
  <transmission name="right_WY_tran">
    <type>transmission_interface/SimpleTransmission</type>
    <joint name="right_WY"/>
    <actuator name="right_WY_motor">
      <hardwareInterface>EffortJointInterface</hardwareInterface>
      <mechanicalReduction>1</mechanicalReduction>
    </actuator>
  </transmission>
  <transmission name="right_WR_tran">
    <type>transmission_interface/SimpleTransmission</type>
    <joint name="right_WR"/>
    <actuator name="right_WR_motor">
      <hardwareInterface>EffortJointInterface</hardwareInterface>
      <mechanicalReduction>1</mechanicalReduction>
    </actuator>
  </transmission>
  <transmission name="right_linkage_tr_tran">
    <type>transmission_interface/SimpleTransmission</type>
    <joint name="right_linkage_tr"/>
    <actuator name="right_linkage_tr_motor">
      <hardwareInterface>EffortJointInterface</hardwareInterface>
      <mechanicalReduction>1</mechanicalReduction>
    </actuator>
  </transmission>
  <transmission name="right_linkage_tl_tran">
    <type>transmission_interface/SimpleTransmission</type>
    <joint name="right_linkage_tl"/>
    <actuator name="right_linkage_tl_motor">
      <hardwareInterface>EffortJointInterface</hardwareInterface>
      <mechanicalReduction>1</mechanicalReduction>
    </actuator>
  </transmission>
  <transmission name="right_linkage_bl_tran">
    <type>transmission_interface/SimpleTransmission</type>
    <joint name="right_linkage_bl"/>
    <actuator name="right_linkage_bl_motor">
      <hardwareInterface>EffortJointInterface</hardwareInterface>
      <mechanicalReduction>1</mechanicalReduction>
    </actuator>
  </transmission>
  <gazebo reference="right_base_link">
    <material>Telerobcar/MetalSeamed</material>
    <selfCollide>false</selfCollide>
  </gazebo>
  <gazebo reference="right_manifold">
    <material>Telerobcar/MetalSeamed</material>
    <selfCollide>false</selfCollide>
  </gazebo>
  <gazebo reference="right_upper_arm">
    <material>Telerobcar/MetalSeamed</material>
    <selfCollide>false</selfCollide>
  </gazebo>
  <gazebo reference="right_elbow_pivot">
    <material>Telerobcar/MetalSeamed</material>
    <selfCollide>false</selfCollide>
  </gazebo>
  <gazebo reference="right_coupling">
    <material>Telerobcar/MetalSeamed</material>
    <selfCollide>false</selfCollide>
  </gazebo>
  <gazebo reference="right_forearm">
    <material>Telerobcar/MetalSeamed</material>
    <selfCollide>false</selfCollide>
  </gazebo>
  <gazebo reference="right_pitch">
    <material>Telerobcar/MetalSeamed</material>
    <selfCollide>false</selfCollide>
  </gazebo>
  <gazebo reference="right_yaw">
    <material>Telerobcar/MetalSeamed</material>
    <selfCollide>false</selfCollide>
  </gazebo>
  <gazebo reference="right_camera">
    <material>Gazebo/FlatBlack</material>
    <selfCollide>false</selfCollide>
    <sensor name="right_camera" type="camera">
      <update_rate>30.0</update_rate>
      <camera name="right_camera">
        <horizontal_fov>1.3962634</horizontal_fov>
        <image>
          <width>800</width>
          <height>800</height>
          <format>R8G8B8</format>
        </image>
        <clip>
          <near>0.02</near>
          <far>300</far>
        </clip>
      </camera>
      <plugin filename="libgazebo_ros_camera.so" name="camera_controller">
        <alwaysOn>true</alwaysOn>
        <updateRate>0.0</updateRate>
        <cameraName>right_camera</cameraName>
        <imageTopicName>image_raw</imageTopicName>
        <cameraInfoTopicName>camera_info</cameraInfoTopicName>
        <frameName>right_camera</frameName>
        <hackBaseline>0.07</hackBaseline>
        <distortionK1>0.0</distortionK1>
        <distortionK2>0.0</distortionK2>
        <distortionK3>0.0</distortionK3>
        <distortionT1>0.0</distortionT1>
        <distortionT2>0.0</distortionT2>
      </plugin>
    </sensor>
  </gazebo>
  <!-- Create the grippers -->
  <link name="left_gripper_base">
    <visual>
      <geometry>
        <mesh filename="package://grips_description/meshes/gripper/gripper_base.dae"/>
      </geometry>
      <material name="metal_seamed"/>
    </visual>
    <collision>
      <geometry>
        <mesh filename="package://grips_description/meshes/gripper/gripper_base.dae"/>
      </geometry>
    </collision>
    <inertial>
      <origin rpy="0 0 0" xyz="0 26.28e-3 0"/>
      <mass value="0.923"/>
      <inertia ixx="0.003" ixy="0.0" ixz="0.0" iyy="0.003" iyz="0.0" izz="0.006"/>
    </inertial>
  </link>
  <link name="left_r_outer">
    <visual>
      <geometry>
        <mesh filename="package://grips_description/meshes/gripper/outer_pivot.dae"/>
      </geometry>
      <material name="metal_seamed"/>
    </visual>
    <collision>
      <geometry>
        <mesh filename="package://grips_description/meshes/gripper/outer_pivot.dae"/>
      </geometry>
    </collision>
    <inertial>
      <origin rpy="0 0 0" xyz="0 31.725e-3 0"/>
      <mass value="0.091"/>
      <inertia ixx="4.664e-5" ixy="0.0" ixz="0.0" iyy="5.519e-6" iyz="0.0" izz="4.682e-5"/>
    </inertial>
  </link>
  <link name="left_l_outer">
    <visual>
      <geometry>
        <mesh filename="package://grips_description/meshes/gripper/outer_pivot.dae"/>
      </geometry>
      <material name="metal_seamed"/>
    </visual>
    <collision>
      <geometry>
        <mesh filename="package://grips_description/meshes/gripper/outer_pivot.dae"/>
      </geometry>
    </collision>
    <inertial>
      <origin rpy="0 0 0" xyz="0 31.725e-3 0"/>
      <mass value="0.091"/>
      <inertia ixx="4.664e-5" ixy="0.0" ixz="0.0" iyy="5.519e-6" iyz="0.0" izz="4.682e-5"/>
    </inertial>
  </link>
  <link name="left_r_inner">
    <visual>
      <geometry>
        <mesh filename="package://grips_description/meshes/gripper/r_inner_pivot.dae"/>
      </geometry>
      <material name="metal_seamed"/>
    </visual>
    <collision>
      <geometry>
        <mesh filename="package://grips_description/meshes/gripper/r_inner_pivot.dae"/>
      </geometry>
    </collision>
    <inertial>
      <origin rpy="0 0 0" xyz="-0.316e-3 23.873e-3 0"/>
      <mass value="0.194"/>
      <inertia ixx="1.179e-4" ixy="1.347e-6" ixz="0.0" iyy="5.647e-5" iyz="0.0" izz="7.353e-5"/>
    </inertial>
  </link>
  <link name="left_l_inner">
    <visual>
      <geometry>
        <mesh filename="package://grips_description/meshes/gripper/l_inner_pivot.dae"/>
      </geometry>
      <material name="metal_seamed"/>
    </visual>
    <collision>
      <geometry>
        <mesh filename="package://grips_description/meshes/gripper/l_inner_pivot.dae"/>
      </geometry>
    </collision>
    <inertial>
      <origin rpy="0 0 0" xyz="0.316e-3 23.873e-3 0"/>
      <mass value="0.194"/>
      <inertia ixx="1.179e-4" ixy="-1.347e-6" ixz="0.0" iyy="5.647e-5" iyz="0.0" izz="7.353e-5"/>
    </inertial>
  </link>
  <link name="left_r_finger">
    <visual>
      <geometry>
        <mesh filename="package://grips_description/meshes/gripper/r_finger.dae"/>
      </geometry>
      <material name="metal_seamed"/>
    </visual>
    <collision>
      <geometry>
        <mesh filename="package://grips_description/meshes/gripper/r_finger.dae"/>
      </geometry>
    </collision>
    <inertial>
      <origin rpy="0 0 0" xyz="3.441e-3 20.353e-3 0"/>
      <mass value="0.174"/>
      <inertia ixx="1.65e-4" ixy="3.16e-5" ixz="0.0" iyy="3.595e-5" iyz="0.0" izz="1.701e-4"/>
    </inertial>
  </link>
  <link name="left_l_finger">
    <visual>
      <geometry>
        <mesh filename="package://grips_description/meshes/gripper/l_finger.dae"/>
      </geometry>
      <material name="metal_seamed"/>
    </visual>
    <collision>
      <geometry>
        <mesh filename="package://grips_description/meshes/gripper/l_finger.dae"/>
      </geometry>
    </collision>
    <inertial>
      <origin rpy="0 0 0" xyz="-3.441e-3 20.353e-3 0"/>
      <mass value="0.174"/>
      <inertia ixx="1.65e-4" ixy="-3.16e-5" ixz="0.0" iyy="3.595e-5" iyz="0.0" izz="1.701e-4"/>
    </inertial>
  </link>
  <joint name="left_r_inner" type="revolute">
    <child link="left_r_inner"/>
    <parent link="left_gripper_base"/>
    <axis xyz="0 0 1"/>
    <origin rpy="0 0 0" xyz="31.737e-3 42.19e-3 0"/>
    <limit effort="200" lower="-1.43" upper="0.4" velocity="15"/>
    <dynamics damping="0.1"/>
  </joint>
  <joint name="left_l_inner" type="revolute">
    <child link="left_l_inner"/>
    <parent link="left_gripper_base"/>
    <axis xyz="0 0 1"/>
    <origin rpy="0 0 0" xyz="-31.737e-3 42.19e-3 0"/>
    <limit effort="200" lower="-0.4" upper="1.43" velocity="15"/>
    <dynamics damping="0.1"/>
  </joint>
  <joint name="left_r_outer" type="revolute">
    <child link="left_r_outer"/>
    <parent link="left_gripper_base"/>
    <axis xyz="0 0 1"/>
    <origin rpy="0 0 0" xyz="58.93e-3 26.49e-3 0"/>
    <limit effort="200" lower="-1.43" upper="0.4" velocity="15"/>
    <dynamics damping="0.1"/>
  </joint>
  <joint name="left_l_outer" type="revolute">
    <child link="left_l_outer"/>
    <parent link="left_gripper_base"/>
    <axis xyz="0 0 1"/>
    <origin rpy="0 0 0" xyz="-58.93e-3 26.49e-3 0"/>
    <limit effort="200" lower="-0.4" upper="1.43" velocity="15"/>
    <dynamics damping="0.1"/>
  </joint>
  <joint name="left_r_finger" type="revolute">
    <child link="left_r_finger"/>
    <parent link="left_r_inner"/>
    <axis xyz="0 0 1"/>
    <origin rpy="0 0 0" xyz="0 63.45e-3 0"/>
    <limit effort="200" lower="-1.57079632679" upper="1.57079632679" velocity="15"/>
    <dynamics damping="0.1"/>
  </joint>
  <joint name="left_l_finger" type="revolute">
    <child link="left_l_finger"/>
    <parent link="left_l_inner"/>
    <axis xyz="0 0 1"/>
    <origin rpy="0 0 0" xyz="0 63.45e-3 0"/>
    <limit effort="200" lower="-1.57079632679" upper="1.57079632679" velocity="15"/>
    <dynamics damping="0.1"/>
  </joint>
  <transmission name="left_r_outer_tran">
    <type>transmission_interface/SimpleTransmission</type>
    <joint name="left_r_outer"/>
    <actuator name="left_r_outer_motor">
      <hardwareInterface>EffortJointInterface</hardwareInterface>
      <mechanicalReduction>1</mechanicalReduction>
    </actuator>
  </transmission>
  <transmission name="left_l_outer_tran">
    <type>transmission_interface/SimpleTransmission</type>
    <joint name="left_l_outer"/>
    <actuator name="left_l_outer_motor">
      <hardwareInterface>EffortJointInterface</hardwareInterface>
      <mechanicalReduction>1</mechanicalReduction>
    </actuator>
  </transmission>
  <transmission name="left_r_inner_tran">
    <type>transmission_interface/SimpleTransmission</type>
    <joint name="left_r_inner"/>
    <actuator name="left_r_inner_motor">
      <hardwareInterface>EffortJointInterface</hardwareInterface>
      <mechanicalReduction>1</mechanicalReduction>
    </actuator>
  </transmission>
  <transmission name="left_l_inner_tran">
    <type>transmission_interface/SimpleTransmission</type>
    <joint name="left_l_inner"/>
    <actuator name="left_l_inner_motor">
      <hardwareInterface>EffortJointInterface</hardwareInterface>
      <mechanicalReduction>1</mechanicalReduction>
    </actuator>
  </transmission>
  <transmission name="left_r_finger_tran">
    <type>transmission_interface/SimpleTransmission</type>
    <joint name="left_r_finger"/>
    <actuator name="left_r_finger_motor">
      <hardwareInterface>EffortJointInterface</hardwareInterface>
      <mechanicalReduction>1</mechanicalReduction>
    </actuator>
  </transmission>
  <transmission name="left_l_finger_tran">
    <type>transmission_interface/SimpleTransmission</type>
    <joint name="left_l_finger"/>
    <actuator name="left_l_finger_motor">
      <hardwareInterface>EffortJointInterface</hardwareInterface>
      <mechanicalReduction>1</mechanicalReduction>
    </actuator>
  </transmission>
  <gazebo reference="left_gripper_base">
    <material>Telerobcar/MetalSeamed</material>
    <selfCollide>false</selfCollide>
  </gazebo>
  <gazebo reference="left_r_outer">
    <material>Telerobcar/MetalSeamed</material>
    <selfCollide>false</selfCollide>
  </gazebo>
  <gazebo reference="left_l_outer">
    <material>Telerobcar/MetalSeamed</material>
    <selfCollide>false</selfCollide>
  </gazebo>
  <gazebo reference="left_r_inner">
    <material>Telerobcar/MetalSeamed</material>
    <selfCollide>false</selfCollide>
  </gazebo>
  <gazebo reference="left_l_inner">
    <material>Telerobcar/MetalSeamed</material>
    <selfCollide>false</selfCollide>
  </gazebo>
  <gazebo reference="left_r_finger">
    <material>Telerobcar/MetalSeamed</material>
    <selfCollide>false</selfCollide>
    <mu1>1.1</mu1>
    <mu2>1.1</mu2>
    <fdir1>0 0 1</fdir1>
    <kp>1000000.0</kp>
    <kd>10.0</kd>
    <maxVel>0.1</maxVel>
    <minDepth>0.001</minDepth>
    <maxContacts>5</maxContacts>
  </gazebo>
  <gazebo reference="left_l_finger">
    <material>Telerobcar/MetalSeamed</material>
    <selfCollide>false</selfCollide>
    <mu1>1.1</mu1>
    <mu2>1.1</mu2>
    <fdir1>0 0 1</fdir1>
    <kp>1000000.0</kp>
    <kd>100.0</kd>
    <maxVel>0.1</maxVel>
    <minDepth>0.001</minDepth>
    <maxContacts>5</maxContacts>
  </gazebo>
  <gazebo>
    <gripper name="left_grasping">
      <grasp_check>
        <attach_steps>1</attach_steps>
        <!-- default: 20 -->
        <detach_steps>1</detach_steps>
        <!-- default: 40 -->
        <min_contact_count>2</min_contact_count>
      </grasp_check>
      <gripper_link>left_r_finger</gripper_link>
      <gripper_link>left_l_finger</gripper_link>
      <palm_link>left_gripper_base</palm_link>
    </gripper>
  </gazebo>
  <link name="right_gripper_base">
    <visual>
      <geometry>
        <mesh filename="package://grips_description/meshes/gripper/gripper_base.dae"/>
      </geometry>
      <material name="metal_seamed"/>
    </visual>
    <collision>
      <geometry>
        <mesh filename="package://grips_description/meshes/gripper/gripper_base.dae"/>
      </geometry>
    </collision>
    <inertial>
      <origin rpy="0 0 0" xyz="0 26.28e-3 0"/>
      <mass value="0.923"/>
      <inertia ixx="0.003" ixy="0.0" ixz="0.0" iyy="0.003" iyz="0.0" izz="0.006"/>
    </inertial>
  </link>
  <link name="right_r_outer">
    <visual>
      <geometry>
        <mesh filename="package://grips_description/meshes/gripper/outer_pivot.dae"/>
      </geometry>
      <material name="metal_seamed"/>
    </visual>
    <collision>
      <geometry>
        <mesh filename="package://grips_description/meshes/gripper/outer_pivot.dae"/>
      </geometry>
    </collision>
    <inertial>
      <origin rpy="0 0 0" xyz="0 31.725e-3 0"/>
      <mass value="0.091"/>
      <inertia ixx="4.664e-5" ixy="0.0" ixz="0.0" iyy="5.519e-6" iyz="0.0" izz="4.682e-5"/>
    </inertial>
  </link>
  <link name="right_l_outer">
    <visual>
      <geometry>
        <mesh filename="package://grips_description/meshes/gripper/outer_pivot.dae"/>
      </geometry>
      <material name="metal_seamed"/>
    </visual>
    <collision>
      <geometry>
        <mesh filename="package://grips_description/meshes/gripper/outer_pivot.dae"/>
      </geometry>
    </collision>
    <inertial>
      <origin rpy="0 0 0" xyz="0 31.725e-3 0"/>
      <mass value="0.091"/>
      <inertia ixx="4.664e-5" ixy="0.0" ixz="0.0" iyy="5.519e-6" iyz="0.0" izz="4.682e-5"/>
    </inertial>
  </link>
  <link name="right_r_inner">
    <visual>
      <geometry>
        <mesh filename="package://grips_description/meshes/gripper/r_inner_pivot.dae"/>
      </geometry>
      <material name="metal_seamed"/>
    </visual>
    <collision>
      <geometry>
        <mesh filename="package://grips_description/meshes/gripper/r_inner_pivot.dae"/>
      </geometry>
    </collision>
    <inertial>
      <origin rpy="0 0 0" xyz="-0.316e-3 23.873e-3 0"/>
      <mass value="0.194"/>
      <inertia ixx="1.179e-4" ixy="1.347e-6" ixz="0.0" iyy="5.647e-5" iyz="0.0" izz="7.353e-5"/>
    </inertial>
  </link>
  <link name="right_l_inner">
    <visual>
      <geometry>
        <mesh filename="package://grips_description/meshes/gripper/l_inner_pivot.dae"/>
      </geometry>
      <material name="metal_seamed"/>
    </visual>
    <collision>
      <geometry>
        <mesh filename="package://grips_description/meshes/gripper/l_inner_pivot.dae"/>
      </geometry>
    </collision>
    <inertial>
      <origin rpy="0 0 0" xyz="0.316e-3 23.873e-3 0"/>
      <mass value="0.194"/>
      <inertia ixx="1.179e-4" ixy="-1.347e-6" ixz="0.0" iyy="5.647e-5" iyz="0.0" izz="7.353e-5"/>
    </inertial>
  </link>
  <link name="right_r_finger">
    <visual>
      <geometry>
        <mesh filename="package://grips_description/meshes/gripper/r_finger.dae"/>
      </geometry>
      <material name="metal_seamed"/>
    </visual>
    <collision>
      <geometry>
        <mesh filename="package://grips_description/meshes/gripper/r_finger.dae"/>
      </geometry>
    </collision>
    <inertial>
      <origin rpy="0 0 0" xyz="3.441e-3 20.353e-3 0"/>
      <mass value="0.174"/>
      <inertia ixx="1.65e-4" ixy="3.16e-5" ixz="0.0" iyy="3.595e-5" iyz="0.0" izz="1.701e-4"/>
    </inertial>
  </link>
  <link name="right_l_finger">
    <visual>
      <geometry>
        <mesh filename="package://grips_description/meshes/gripper/l_finger.dae"/>
      </geometry>
      <material name="metal_seamed"/>
    </visual>
    <collision>
      <geometry>
        <mesh filename="package://grips_description/meshes/gripper/l_finger.dae"/>
      </geometry>
    </collision>
    <inertial>
      <origin rpy="0 0 0" xyz="-3.441e-3 20.353e-3 0"/>
      <mass value="0.174"/>
      <inertia ixx="1.65e-4" ixy="-3.16e-5" ixz="0.0" iyy="3.595e-5" iyz="0.0" izz="1.701e-4"/>
    </inertial>
  </link>
  <joint name="right_r_inner" type="revolute">
    <child link="right_r_inner"/>
    <parent link="right_gripper_base"/>
    <axis xyz="0 0 1"/>
    <origin rpy="0 0 0" xyz="31.737e-3 42.19e-3 0"/>
    <limit effort="200" lower="-1.43" upper="0.4" velocity="15"/>
    <dynamics damping="0.1"/>
  </joint>
  <joint name="right_l_inner" type="revolute">
    <child link="right_l_inner"/>
    <parent link="right_gripper_base"/>
    <axis xyz="0 0 1"/>
    <origin rpy="0 0 0" xyz="-31.737e-3 42.19e-3 0"/>
    <limit effort="200" lower="-0.4" upper="1.43" velocity="15"/>
    <dynamics damping="0.1"/>
  </joint>
  <joint name="right_r_outer" type="revolute">
    <child link="right_r_outer"/>
    <parent link="right_gripper_base"/>
    <axis xyz="0 0 1"/>
    <origin rpy="0 0 0" xyz="58.93e-3 26.49e-3 0"/>
    <limit effort="200" lower="-1.43" upper="0.4" velocity="15"/>
    <dynamics damping="0.1"/>
  </joint>
  <joint name="right_l_outer" type="revolute">
    <child link="right_l_outer"/>
    <parent link="right_gripper_base"/>
    <axis xyz="0 0 1"/>
    <origin rpy="0 0 0" xyz="-58.93e-3 26.49e-3 0"/>
    <limit effort="200" lower="-0.4" upper="1.43" velocity="15"/>
    <dynamics damping="0.1"/>
  </joint>
  <joint name="right_r_finger" type="revolute">
    <child link="right_r_finger"/>
    <parent link="right_r_inner"/>
    <axis xyz="0 0 1"/>
    <origin rpy="0 0 0" xyz="0 63.45e-3 0"/>
    <limit effort="200" lower="-1.57079632679" upper="1.57079632679" velocity="15"/>
    <dynamics damping="0.1"/>
  </joint>
  <joint name="right_l_finger" type="revolute">
    <child link="right_l_finger"/>
    <parent link="right_l_inner"/>
    <axis xyz="0 0 1"/>
    <origin rpy="0 0 0" xyz="0 63.45e-3 0"/>
    <limit effort="200" lower="-1.57079632679" upper="1.57079632679" velocity="15"/>
    <dynamics damping="0.1"/>
  </joint>
  <transmission name="right_r_outer_tran">
    <type>transmission_interface/SimpleTransmission</type>
    <joint name="right_r_outer"/>
    <actuator name="right_r_outer_motor">
      <hardwareInterface>EffortJointInterface</hardwareInterface>
      <mechanicalReduction>1</mechanicalReduction>
    </actuator>
  </transmission>
  <transmission name="right_l_outer_tran">
    <type>transmission_interface/SimpleTransmission</type>
    <joint name="right_l_outer"/>
    <actuator name="right_l_outer_motor">
      <hardwareInterface>EffortJointInterface</hardwareInterface>
      <mechanicalReduction>1</mechanicalReduction>
    </actuator>
  </transmission>
  <transmission name="right_r_inner_tran">
    <type>transmission_interface/SimpleTransmission</type>
    <joint name="right_r_inner"/>
    <actuator name="right_r_inner_motor">
      <hardwareInterface>EffortJointInterface</hardwareInterface>
      <mechanicalReduction>1</mechanicalReduction>
    </actuator>
  </transmission>
  <transmission name="right_l_inner_tran">
    <type>transmission_interface/SimpleTransmission</type>
    <joint name="right_l_inner"/>
    <actuator name="right_l_inner_motor">
      <hardwareInterface>EffortJointInterface</hardwareInterface>
      <mechanicalReduction>1</mechanicalReduction>
    </actuator>
  </transmission>
  <transmission name="right_r_finger_tran">
    <type>transmission_interface/SimpleTransmission</type>
    <joint name="right_r_finger"/>
    <actuator name="right_r_finger_motor">
      <hardwareInterface>EffortJointInterface</hardwareInterface>
      <mechanicalReduction>1</mechanicalReduction>
    </actuator>
  </transmission>
  <transmission name="right_l_finger_tran">
    <type>transmission_interface/SimpleTransmission</type>
    <joint name="right_l_finger"/>
    <actuator name="right_l_finger_motor">
      <hardwareInterface>EffortJointInterface</hardwareInterface>
      <mechanicalReduction>1</mechanicalReduction>
    </actuator>
  </transmission>
  <gazebo reference="right_gripper_base">
    <material>Telerobcar/MetalSeamed</material>
    <selfCollide>false</selfCollide>
  </gazebo>
  <gazebo reference="right_r_outer">
    <material>Telerobcar/MetalSeamed</material>
    <selfCollide>false</selfCollide>
  </gazebo>
  <gazebo reference="right_l_outer">
    <material>Telerobcar/MetalSeamed</material>
    <selfCollide>false</selfCollide>
  </gazebo>
  <gazebo reference="right_r_inner">
    <material>Telerobcar/MetalSeamed</material>
    <selfCollide>false</selfCollide>
  </gazebo>
  <gazebo reference="right_l_inner">
    <material>Telerobcar/MetalSeamed</material>
    <selfCollide>false</selfCollide>
  </gazebo>
  <gazebo reference="right_r_finger">
    <material>Telerobcar/MetalSeamed</material>
    <selfCollide>false</selfCollide>
    <mu1>1.1</mu1>
    <mu2>1.1</mu2>
    <fdir1>0 0 1</fdir1>
    <kp>1000000.0</kp>
    <kd>10.0</kd>
    <maxVel>0.1</maxVel>
    <minDepth>0.001</minDepth>
    <maxContacts>5</maxContacts>
  </gazebo>
  <gazebo reference="right_l_finger">
    <material>Telerobcar/MetalSeamed</material>
    <selfCollide>false</selfCollide>
    <mu1>1.1</mu1>
    <mu2>1.1</mu2>
    <fdir1>0 0 1</fdir1>
    <kp>1000000.0</kp>
    <kd>100.0</kd>
    <maxVel>0.1</maxVel>
    <minDepth>0.001</minDepth>
    <maxContacts>5</maxContacts>
  </gazebo>
  <gazebo>
    <gripper name="right_grasping">
      <grasp_check>
        <attach_steps>1</attach_steps>
        <!-- default: 20 -->
        <detach_steps>1</detach_steps>
        <!-- default: 40 -->
        <min_contact_count>2</min_contact_count>
      </grasp_check>
      <gripper_link>right_r_finger</gripper_link>
      <gripper_link>right_l_finger</gripper_link>
      <palm_link>right_gripper_base</palm_link>
    </gripper>
  </gazebo>
  <!-- Used for fixing the gripper to the robot -->
  <joint name="left_gripper_anchor" type="fixed">
    <origin rpy="0 0 0" xyz="0 0 0"/>
    <parent link="left_end_effector"/>
    <child link="left_gripper_base"/>
  </joint>
  <!-- Used for fixing the gripper to the robot -->
  <joint name="right_gripper_anchor" type="fixed">
    <origin rpy="0 0 0" xyz="0 0 0"/>
    <parent link="right_end_effector"/>
    <child link="right_gripper_base"/>
  </joint>
  <!-- Used for fixing the robots to Gazebo -->
  <link name="world"/>
  <joint name="left_anchor" type="fixed">
    <origin rpy="0 0 0" xyz="0 0 0.801"/>
    <parent link="world"/>
    <child link="left_base_link"/>
  </joint>
  <joint name="right_anchor" type="fixed">
    <origin rpy="0 0 0" xyz="1 0 0.801"/>
    <parent link="world"/>
    <child link="right_base_link"/>
  </joint>
  <!-- ros_control plugin -->
  <gazebo>
    <plugin filename="libgazebo_ros_control.so" name="ros_control">
		</plugin>
  </gazebo>
</robot>
