<?xml version="1.0" ?>
<!-- =================================================================================== -->
<!-- |    This document was autogenerated by xacro from grips_robotiq.xacro            | -->
<!-- |    EDITING THIS FILE BY HAND IS NOT RECOMMENDED                                 | -->
<!-- =================================================================================== -->
<robot name="grips" xmlns:xacro="http://ros.org/wiki/xacro">
  <!-- Import common macros-->
  <!-- Import materials for rviz-->
  <material name="black">
    <color rgba="0.0 0.0 0.0 1.0"/>
  </material>
  <material name="blue">
    <color rgba="0.0 0.0 0.8 1.0"/>
  </material>
  <material name="green">
    <color rgba="0.0 0.8 0.0 1.0"/>
  </material>
  <material name="grey">
    <color rgba="0.2 0.2 0.2 1.0"/>
  </material>
  <material name="orange">
    <color rgba="1.0 0.423529411765 0.0392156862745 1.0"/>
  </material>
  <material name="brown">
    <color rgba="0.870588235294 0.811764705882 0.764705882353 1.0"/>
  </material>
  <material name="red">
    <color rgba="0.8 0.0 0.0 1.0"/>
  </material>
  <material name="white">
    <color rgba="1.0 1.0 1.0 1.0"/>
  </material>
  <material name="metal_seamed">
    <color rgba="0.4627450980392157 0.4666666666666667 0.4509803921568628 1.0"/>
  </material>
  <!-- Import robot without gripper -->
  <!-- Import ft sensor -->
  <!-- Import imu sensor -->
  <!-- Import robotiq s model -->
  <!-- Create the grips robot -->
  <link name="base_link">
    <visual>
      <geometry>
        <mesh filename="package://grips_description/meshes/visual/base.dae"/>
      </geometry>
      <material name="black"/>
    </visual>
    <collision>
      <geometry>
        <mesh filename="package://grips_description/meshes/collision/base.dae"/>
      </geometry>
    </collision>
    <inertial>
      <origin rpy="0 0 0" xyz="0 0 7e-3"/>
      <mass value="1.208"/>
      <inertia ixx="0.003" ixy="0.0" ixz="0.0" iyy="0.003" iyz="0.0" izz="0.006"/>
    </inertial>
  </link>
  <link name="manifold">
    <visual>
      <geometry>
        <mesh filename="package://grips_description/meshes/visual/manifold.dae"/>
      </geometry>
      <material name="blue"/>
    </visual>
    <collision>
      <geometry>
        <mesh filename="package://grips_description/meshes/collision/manifold.dae"/>
      </geometry>
    </collision>
    <inertial>
      <origin rpy="0 0 0" xyz="0 2e-3 0.21"/>
      <mass value="41.111"/>
      <inertia ixx="0.549" ixy="-9.556e-5" ixz="-5.871e-5" iyy="0.855" iyz="2e-3" izz="0.605"/>
    </inertial>
  </link>
  <link name="upper_arm">
    <visual>
      <geometry>
        <mesh filename="package://grips_description/meshes/visual/upper_arm.dae"/>
      </geometry>
      <material name="black"/>
    </visual>
    <collision>
      <geometry>
        <mesh filename="package://grips_description/meshes/collision/upper_arm.dae"/>
      </geometry>
    </collision>
    <inertial>
      <origin rpy="0 0 0" xyz="0 5e-3 0.227"/>
      <mass value="3.592"/>
      <inertia ixx="0.103" ixy="0" ixz="0" iyy="0.106" iyz="0.004" izz="0.013"/>
    </inertial>
  </link>
  <link name="elbow_pivot">
    <visual>
      <geometry>
        <mesh filename="package://grips_description/meshes/visual/elbow_pivot.dae"/>
      </geometry>
      <material name="black"/>
    </visual>
    <collision>
      <geometry>
        <mesh filename="package://grips_description/meshes/visual/elbow_pivot.dae"/>
      </geometry>
    </collision>
    <inertial>
      <origin rpy="0 0 0" xyz="-3.6e-10 80.686e-3 -6.33e-5"/>
      <mass value="0.72"/>
      <inertia ixx="0.002" ixy="-3.231e-27" ixz="0" iyy="3.397e-4" iyz="-1.919e-5" izz="0.002"/>
    </inertial>
  </link>
  <link name="coupling">
    <visual>
      <geometry>
        <mesh filename="package://grips_description/meshes/visual/coupling.dae"/>
      </geometry>
      <material name="black"/>
    </visual>
    <collision>
      <geometry>
        <mesh filename="package://grips_description/meshes/visual/coupling.dae"/>
      </geometry>
    </collision>
    <inertial>
      <origin rpy="0 0 0" xyz="0 0 -0.26035"/>
      <mass value="0.446"/>
      <inertia ixx="0.011" ixy="-3.231e-27" ixz="0" iyy="0.011" iyz="0" izz="2.102e-5"/>
    </inertial>
  </link>
  <link name="forearm">
    <visual>
      <geometry>
        <mesh filename="package://grips_description/meshes/visual/forearm.dae"/>
      </geometry>
      <material name="black"/>
    </visual>
    <collision>
      <geometry>
        <mesh filename="package://grips_description/meshes/collision/forearm.dae"/>
      </geometry>
    </collision>
    <inertial>
      <origin rpy="0 0 0" xyz="0 0.155337 0.012119"/>
      <mass value="4.935"/>
      <inertia ixx="0.073" ixy="0" ixz="0" iyy="0.009" iyz="0.004" izz="0.073"/>
    </inertial>
  </link>
  <link name="pitch">
    <visual>
      <geometry>
        <mesh filename="package://grips_description/meshes/visual/pitch.dae"/>
      </geometry>
      <material name="black"/>
    </visual>
    <collision>
      <geometry>
        <mesh filename="package://grips_description/meshes/collision/pitch.dae"/>
      </geometry>
    </collision>
    <inertial>
      <origin rpy="0 0 0" xyz="0 0.065 0"/>
      <mass value="0.679"/>
      <inertia ixx="0.003" ixy="0" ixz="0" iyy="0.002" iyz="0.004" izz="0.002"/>
    </inertial>
  </link>
  <link name="yaw">
    <visual>
      <geometry>
        <mesh filename="package://grips_description/meshes/visual/yaw.dae"/>
      </geometry>
      <material name="black"/>
    </visual>
    <collision>
      <geometry>
        <mesh filename="package://grips_description/meshes/collision/yaw.dae"/>
      </geometry>
    </collision>
    <inertial>
      <origin rpy="0 0 0" xyz="-1e-3 95.791e-3 18.273e-3"/>
      <mass value="4.689"/>
      <inertia ixx="0.027" ixy="1.597e-4" ixz="-2.174e-4" iyy="0.009" iyz="-0.003" izz="0.026"/>
    </inertial>
  </link>
  <link name="end_effector"/>
  <link name="camera">
    <visual>
      <geometry>
        <mesh filename="package://grips_description/meshes/visual/camera.dae"/>
      </geometry>
      <material name="black"/>
    </visual>
    <collision>
      <geometry>
        <mesh filename="package://grips_description/meshes/collision/camera.dae"/>
      </geometry>
    </collision>
    <inertial>
      <origin rpy="0 0 0" xyz="0.077 0.007 0.002"/>
      <mass value="0.869"/>
      <inertia ixx="0.001" ixy="-1.561e-4" ixz="-5.859e-5" iyy="0.002" iyz="3.295e-5" izz="0.002"/>
    </inertial>
  </link>
  <joint name="SA" type="revolute">
    <child link="manifold"/>
    <parent link="base_link"/>
    <axis xyz="0 0 1"/>
    <origin rpy="0 0 0" xyz="0 0 15.24e-3"/>
    <limit effort="200" lower="-1.57079632679" upper="1.57079632679" velocity="1.3962634016"/>
    <dynamics damping="5"/>
  </joint>
  <joint name="SE" type="revolute">
    <child link="upper_arm"/>
    <parent link="manifold"/>
    <axis xyz="1 0 0"/>
    <origin rpy="0 0 0" xyz="0 0 0.33812"/>
    <limit effort="200" lower="-1.57079632679" upper="0.523598775598" velocity="1.1344640138"/>
    <dynamics damping="5" friction="10"/>
  </joint>
  <joint name="linkage_tr" type="revolute">
    <child link="forearm"/>
    <parent link="upper_arm"/>
    <axis xyz="1 0 0"/>
    <origin rpy="0 0 0" xyz="0 -9.82e-3 0.52167"/>
    <limit effort="200" lower="-1.28" upper="1.0471975512" velocity="0.872664625997"/>
    <dynamics damping="10"/>
  </joint>
  <joint name="WP" type="revolute">
    <child link="pitch"/>
    <parent link="forearm"/>
    <axis xyz="1 0 0"/>
    <origin rpy="0 0 0" xyz="0 0.26109 7.5e-3"/>
    <limit effort="200" lower="-0.581" upper="1.1" velocity="1.74532925199"/>
    <dynamics damping="5"/>
  </joint>
  <joint name="WY" type="revolute">
    <child link="yaw"/>
    <parent link="pitch"/>
    <axis xyz="0 0 1"/>
    <origin rpy="0 0 0" xyz="0 0.13322 0"/>
    <limit effort="200" lower="-1.01" upper="0.675" velocity="2.00712863979"/>
    <dynamics damping="5"/>
  </joint>
  <joint name="WR" type="continuous">
    <child link="end_effector"/>
    <parent link="yaw"/>
    <axis xyz="0 1 0"/>
    <origin rpy="0 0 0" xyz="-0.787e-3 0.190892 0.051331"/>
    <limit effort="200" velocity="3.49065850399"/>
    <dynamics damping="0.5"/>
  </joint>
  <joint name="camera_joint" type="fixed">
    <child link="camera"/>
    <parent link="yaw"/>
    <axis xyz="0 1 0"/>
    <origin rpy="0 0.523598775598 1.57079632679" xyz="0 0.095446 0.25"/>
  </joint>
  <joint name="linkage_tl" type="continuous">
    <child link="coupling"/>
    <parent link="forearm"/>
    <axis xyz="1 0 0"/>
    <origin rpy="0.019320795 0 0" xyz="0 -0.123444 0.029845"/>
    <limit effort="200" velocity="5"/>
    <dynamics damping="0.5" friction="0.5"/>
  </joint>
  <joint name="linkage_bl" type="continuous">
    <child link="elbow_pivot"/>
    <parent link="coupling"/>
    <axis xyz="1 0 0"/>
    <origin rpy="-0.24521876 0 0" xyz="0 0 -0.5207"/>
    <limit effort="200" velocity="5"/>
    <dynamics damping="0.5" friction="0.5"/>
  </joint>
  <transmission name="SA_tran">
    <type>transmission_interface/SimpleTransmission</type>
    <joint name="SA"/>
    <actuator name="SA_motor">
      <hardwareInterface>EffortJointInterface</hardwareInterface>
      <mechanicalReduction>1</mechanicalReduction>
    </actuator>
  </transmission>
  <transmission name="SE_tran">
    <type>transmission_interface/SimpleTransmission</type>
    <joint name="SE"/>
    <actuator name="SE_motor">
      <hardwareInterface>EffortJointInterface</hardwareInterface>
      <mechanicalReduction>1</mechanicalReduction>
    </actuator>
  </transmission>
  <transmission name="WP_tran">
    <type>transmission_interface/SimpleTransmission</type>
    <joint name="WP"/>
    <actuator name="WP_motor">
      <hardwareInterface>EffortJointInterface</hardwareInterface>
      <mechanicalReduction>1</mechanicalReduction>
    </actuator>
  </transmission>
  <transmission name="WY_tran">
    <type>transmission_interface/SimpleTransmission</type>
    <joint name="WY"/>
    <actuator name="WY_motor">
      <hardwareInterface>EffortJointInterface</hardwareInterface>
      <mechanicalReduction>1</mechanicalReduction>
    </actuator>
  </transmission>
  <transmission name="WR_tran">
    <type>transmission_interface/SimpleTransmission</type>
    <joint name="WR"/>
    <actuator name="WR_motor">
      <hardwareInterface>EffortJointInterface</hardwareInterface>
      <mechanicalReduction>1</mechanicalReduction>
    </actuator>
  </transmission>
  <transmission name="linkage_tr_tran">
    <type>transmission_interface/SimpleTransmission</type>
    <joint name="linkage_tr"/>
    <actuator name="linkage_tr_motor">
      <hardwareInterface>EffortJointInterface</hardwareInterface>
      <mechanicalReduction>1</mechanicalReduction>
    </actuator>
  </transmission>
  <transmission name="linkage_tl_tran">
    <type>transmission_interface/SimpleTransmission</type>
    <joint name="linkage_tl"/>
    <actuator name="linkage_tl_motor">
      <hardwareInterface>EffortJointInterface</hardwareInterface>
      <mechanicalReduction>1</mechanicalReduction>
    </actuator>
  </transmission>
  <transmission name="linkage_bl_tran">
    <type>transmission_interface/SimpleTransmission</type>
    <joint name="linkage_bl"/>
    <actuator name="linkage_bl_motor">
      <hardwareInterface>EffortJointInterface</hardwareInterface>
      <mechanicalReduction>1</mechanicalReduction>
    </actuator>
  </transmission>
  <gazebo reference="base_link">
    <material>Telerobcar/MetalSeamed</material>
    <selfCollide>false</selfCollide>
  </gazebo>
  <gazebo reference="manifold">
    <material>Telerobcar/MetalSeamed</material>
    <selfCollide>false</selfCollide>
  </gazebo>
  <gazebo reference="upper_arm">
    <material>Telerobcar/MetalSeamed</material>
    <selfCollide>false</selfCollide>
  </gazebo>
  <gazebo reference="elbow_pivot">
    <material>Telerobcar/MetalSeamed</material>
    <selfCollide>false</selfCollide>
  </gazebo>
  <gazebo reference="coupling">
    <material>Telerobcar/MetalSeamed</material>
    <selfCollide>false</selfCollide>
  </gazebo>
  <gazebo reference="forearm">
    <material>Telerobcar/MetalSeamed</material>
    <selfCollide>false</selfCollide>
  </gazebo>
  <gazebo reference="pitch">
    <material>Telerobcar/MetalSeamed</material>
    <selfCollide>false</selfCollide>
  </gazebo>
  <gazebo reference="yaw">
    <material>Telerobcar/MetalSeamed</material>
    <selfCollide>false</selfCollide>
  </gazebo>
  <gazebo reference="end_effector">
    <selfCollide>false</selfCollide>
  </gazebo>
  <gazebo reference="camera">
    <material>Gazebo/FlatBlack</material>
    <selfCollide>false</selfCollide>
    <sensor name="camera" type="camera">
      <update_rate>30.0</update_rate>
      <camera name="camera">
        <horizontal_fov>1.3962634</horizontal_fov>
        <image>
          <width>800</width>
          <height>800</height>
          <format>R8G8B8</format>
        </image>
        <clip>
          <near>0.02</near>
          <far>300</far>
        </clip>
      </camera>
      <plugin filename="libgazebo_ros_camera.so" name="camera_controller">
        <alwaysOn>true</alwaysOn>
        <updateRate>0.0</updateRate>
        <cameraName>camera</cameraName>
        <imageTopicName>image_raw</imageTopicName>
        <cameraInfoTopicName>camera_info</cameraInfoTopicName>
        <frameName>camera</frameName>
        <hackBaseline>0.07</hackBaseline>
        <distortionK1>0.0</distortionK1>
        <distortionK2>0.0</distortionK2>
        <distortionK3>0.0</distortionK3>
        <distortionT1>0.0</distortionT1>
        <distortionT2>0.0</distortionT2>
      </plugin>
    </sensor>
  </gazebo>
  <!-- Add the ft_sensor -->
  <link name="ft_kraft_plate">
    <visual>
      <geometry>
        <mesh filename="package://grips_description/meshes/visual/ft_kraft_plate.dae"/>
      </geometry>
      <material name="black"/>
    </visual>
    <collision>
      <geometry>
        <mesh filename="package://grips_description/meshes/visual/ft_kraft_plate.dae"/>
      </geometry>
    </collision>
    <inertial>
      <origin rpy="0 0 0" xyz="-0.192e-3  1.769e-9    6.143e-3"/>
      <mass value="0.059"/>
      <inertia ixx="8.905e-6" ixy="0.0" ixz="4.509e-8" iyy="8.788e-6" iyz="0.0" izz="1.421e-5"/>
    </inertial>
  </link>
  <link name="ft_wrist_plate">
    <visual>
      <geometry>
        <mesh filename="package://grips_description/meshes/visual/ft_wrist_plate.dae"/>
      </geometry>
      <material name="black"/>
    </visual>
    <collision>
      <geometry>
        <mesh filename="package://grips_description/meshes/visual/ft_wrist_plate.dae"/>
      </geometry>
    </collision>
    <inertial>
      <origin rpy="0 0 0" xyz="-0.057e-3  1.648e-8    17.057e-3"/>
      <mass value="0.1478"/>
      <inertia ixx="4.686e-5" ixy="0.0" ixz="0.0" iyy="4.663e-5" iyz="0.0" izz="8.289e-5"/>
    </inertial>
  </link>
  <link name="ft_sensor">
    <visual>
      <geometry>
        <mesh filename="package://grips_description/meshes/visual/ft_sensor.dae"/>
      </geometry>
      <material name="black"/>
    </visual>
    <collision>
      <geometry>
        <mesh filename="package://grips_description/meshes/visual/ft_sensor.dae"/>
      </geometry>
    </collision>
    <inertial>
      <origin rpy="0 0 0" xyz="9.396e-4   0.017       -7.545e-4"/>
      <mass value="0.2396"/>
      <inertia ixx="1.055e-4" ixy="-7.262e-7" ixz="6.186e-6" iyy="1.7e-4" iyz="6.529e-7" izz="1.076e-4"/>
    </inertial>
  </link>
  <link name="ft_robotiq_plate">
    <visual>
      <geometry>
        <mesh filename="package://grips_description/meshes/visual/ft_robotiq_plate.dae"/>
      </geometry>
      <material name="black"/>
    </visual>
    <collision>
      <geometry>
        <mesh filename="package://grips_description/meshes/visual/ft_robotiq_plate.dae"/>
      </geometry>
    </collision>
    <inertial>
      <origin rpy="0 0 0" xyz="0.0        0.0         5.644e-3"/>
      <mass value="0.2304"/>
      <inertia ixx="9.43e-5" ixy="0.0" ixz="0.0" iyy="9.43e-5" iyz="0.0" izz="1.837e-4"/>
    </inertial>
  </link>
  <link name="ft_end_effector"/>
  <joint name="ft_robot_joint" type="fixed">
    <origin rpy="-1.57079632679 0 0" xyz="0 0 0"/>
    <parent link="end_effector"/>
    <child link="ft_kraft_plate"/>
  </joint>
  <joint name="ft_wrist_joint" type="fixed">
    <origin rpy="0 0 0" xyz="0 0 0"/>
    <parent link="ft_kraft_plate"/>
    <child link="ft_wrist_plate"/>
  </joint>
  <joint name="ft_sensor_joint" type="fixed">
    <origin rpy="-1.57079632679 0 0" xyz="0 0 0.0564"/>
    <parent link="ft_wrist_plate"/>
    <child link="ft_sensor"/>
  </joint>
  <joint name="ft_plate_joint" type="fixed">
    <origin rpy="-1.57079632679 0 0" xyz="0 -11e-3 0"/>
    <parent link="ft_sensor"/>
    <child link="ft_robotiq_plate"/>
  </joint>
  <joint name="ft_end_joint" type="fixed">
    <origin rpy="-1.57079632679 0 0" xyz="0 0 0"/>
    <parent link="ft_robotiq_plate"/>
    <child link="ft_end_effector"/>
  </joint>
  <gazebo reference="WR">
    <provideFeedback>true</provideFeedback>
    <!-- FIXME: This sensor tag is never included in the sdf -->
    <sensor name="force_torque_sensor" type="force_torque">
      <always_on>1</always_on>
      <update_rate>100.0</update_rate>
      <visualize>1</visualize>
      <force_torque name="ft_sensor">
        <frame>child</frame>
      </force_torque>
    </sensor>
    <!-- *************************************************** -->
  </gazebo>
  <gazebo>
    <plugin filename="libgazebo_ros_ft_sensor.so" name="ft_sensor">
      <robotNamespace>/grips_robotiq</robotNamespace>
      <updateRate>100.0</updateRate>
      <topicName>ft_raw</topicName>
      <jointName>WR</jointName>
    </plugin>
  </gazebo>
  <!-- Add the imu_sensor -->
  <link name="imu_sensor">
    <visual>
      <geometry>
        <mesh filename="package://grips_description/meshes/visual/adis1640x.dae"/>
      </geometry>
      <material name="black"/>
    </visual>
    <collision>
      <geometry>
        <mesh filename="package://grips_description/meshes/visual/adis1640x.dae"/>
      </geometry>
    </collision>
    <inertial>
      <origin rpy="0 0 0" xyz="-0.007e-3 11.349e-3 0.153e-3"/>
      <mass value="0.0245"/>
      <inertia ixx="1.181e-6" ixy="-9854e-10" ixz="-6.24e-10" iyy="1.188e-6" iyz="1.978e-8" izz="1.176e-6"/>
    </inertial>
  </link>
  <gazebo reference="imu_sensor">
    <material>Telerobcar/MetalSeamed</material>
    <turnGravityOff>false</turnGravityOff>
  </gazebo>
  <link name="imu_board">
    <inertial>
      <mass value="0.059"/>
      <origin xyz="0 0 0"/>
      <!--The 3x3 rotational inertia matrix. -->
      <inertia ixx="2.14988059583e-05" ixy="0" ixz="0" iyy="2.06820065167e-05" iyz="0" izz="2.06820065167e-05"/>
    </inertial>
    <visual>
      <origin rpy="0 0 0" xyz="0 0 0"/>
      <geometry>
        <box size="0.06477 0.06604 0.00337"/>
      </geometry>
      <material name="green"/>
    </visual>
    <collision>
      <origin rpy="0 0 0 " xyz="0 0 0"/>
      <geometry>
        <box size="0.06477 0.06604 0.00337"/>
      </geometry>
    </collision>
  </link>
  <gazebo reference="imu_board">
    <material>Gazebo/Green</material>
    <turnGravityOff>false</turnGravityOff>
  </gazebo>
  <joint name="board_joint" type="fixed">
    <origin rpy="0 0 -1.57079632679" xyz="0 0.13 0.067005"/>
    <parent link="end_effector"/>
    <child link="imu_board"/>
  </joint>
  <joint name="imu_joint" type="fixed">
    <origin rpy="0 0 0" xyz="0 0 0.002435"/>
    <parent link="imu_board"/>
    <child link="imu_sensor"/>
  </joint>
  <gazebo>
    <plugin filename="libgazebo_ros_imu.so" name="imu_sensor">
      <robotNamespace>/grips_robotiq</robotNamespace>
      <updateRate>500.0</updateRate>
      <topicName>imu</topicName>
      <bodyName>imu_board</bodyName>
    </plugin>
  </gazebo>
  <!-- Add robotiq hand -->
  <link name="finger_1_link_0">
    <visual>
      <origin rpy="0 0 0" xyz="0.020 0 0"/>
      <geometry>
        <mesh filename="package://robotiq_s_model_visualization/meshes/s-model_articulated/visual/link_0.STL"/>
      </geometry>
      <material name="green">
        <color rgba="0 1 0 1"/>
      </material>
    </visual>
    <collision>
      <origin rpy="0 3.1416 -1.57" xyz="-0.0455 0.0414 0.036"/>
      <geometry>
        <mesh filename="package://robotiq_s_model_visualization/meshes/s-model_articulated/collision/link_0.STL"/>
      </geometry>
      <material name="yellow">
        <color rgba="0 1 1 1"/>
      </material>
    </collision>
    <inertial>
      <origin rpy="0 0 0" xyz="0 0 0"/>
      <mass value="0.05"/>
      <inertia ixx="0.01" ixy="-0.00002" ixz="0.00001" iyy="0.0008" iyz="0" izz="0.001"/>
    </inertial>
  </link>
  <link name="finger_1_link_1">
    <visual>
      <origin rpy="0 0 -0.52" xyz="0.050 -.028 0"/>
      <geometry>
        <mesh filename="package://robotiq_s_model_visualization/meshes/s-model_articulated/visual/link_1.STL"/>
      </geometry>
      <material name="green"/>
    </visual>
    <collision>
      <origin rpy="0 0 -0.52" xyz="0.050 -.028 0"/>
      <geometry>
        <mesh filename="package://robotiq_s_model_visualization/meshes/s-model_articulated/collision/link_1.STL"/>
      </geometry>
      <material name="yellow"/>
    </collision>
    <inertial>
      <origin rpy="0 0 0" xyz="0 0 0"/>
      <mass value="0.15"/>
      <inertia ixx="0.001859" ixy="-0.000376" ixz="0.000028" iyy="0.012756" iyz="0" izz="0.0024"/>
    </inertial>
  </link>
  <link name="finger_1_link_2">
    <!--
			NOTE: This link has an offset in the z-direction based on the models that were
			used to generate grap-it poses.  With the offset below the model appears visually
			correct, but it is suspect.
			-->
    <visual>
      <origin rpy="0 0 0" xyz="0.039 0 0.0075"/>
      <geometry>
        <mesh filename="package://robotiq_s_model_visualization/meshes/s-model_articulated/visual/link_2.STL"/>
      </geometry>
      <material name="green"/>
    </visual>
    <collision>
      <origin rpy="0 0 0" xyz="0.039 0 0.0075"/>
      <geometry>
        <mesh filename="package://robotiq_s_model_visualization/meshes/s-model_articulated/collision/link_2.STL"/>
      </geometry>
      <material name="yellow"/>
    </collision>
    <inertial>
      <origin rpy="0 0 0" xyz="0 0 0"/>
      <mass value="0.15"/>
      <inertia ixx="0.001859" ixy="-0.000376" ixz="0.000028" iyy="0.012756" iyz="0" izz="0.0024"/>
    </inertial>
  </link>
  <link name="finger_1_link_3">
    <visual>
      <origin rpy="0 0 0.52" xyz="0 0 0"/>
      <geometry>
        <mesh filename="package://robotiq_s_model_visualization/meshes/s-model_articulated/visual/link_3.STL"/>
      </geometry>
      <material name="green"/>
    </visual>
    <collision>
      <origin rpy="0 0 0.52" xyz="0 0 0"/>
      <geometry>
        <mesh filename="package://robotiq_s_model_visualization/meshes/s-model_articulated/collision/link_3.STL"/>
      </geometry>
      <material name="yellow"/>
    </collision>
    <inertial>
      <origin rpy="0 0 0" xyz="0 0 0"/>
      <mass value="0.05"/>
      <inertia ixx="0.001239" ixy="-0.000251" ixz="0.000019" iyy="0.00085" iyz="0" izz="0.001632"/>
    </inertial>
  </link>
  <joint name="finger_1_joint_1" type="revolute">
    <parent link="finger_1_link_0"/>
    <child link="finger_1_link_1"/>
    <axis xyz="0 0 1"/>
    <origin rpy="0 0 0" xyz="0.020 0 0"/>
    <limit effort="100" lower="0" upper="3.1416" velocity="100"/>
  </joint>
  <joint name="finger_1_joint_2" type="revolute">
    <parent link="finger_1_link_1"/>
    <child link="finger_1_link_2"/>
    <axis xyz="0 0 1"/>
    <origin rpy="0 0 -0.52" xyz="0.050 -.028 0"/>
    <limit effort="100" lower="0" upper="3.1416" velocity="100"/>
  </joint>
  <joint name="finger_1_joint_3" type="revolute">
    <parent link="finger_1_link_2"/>
    <child link="finger_1_link_3"/>
    <axis xyz="0 0 1"/>
    <origin rpy="0 0 0" xyz="0.039 0 0"/>
    <limit effort="100" lower="0" upper="3.1416" velocity="100"/>
  </joint>
  <link name="finger_2_link_0">
    <visual>
      <origin rpy="0 0 0" xyz="0.020 0 0"/>
      <geometry>
        <mesh filename="package://robotiq_s_model_visualization/meshes/s-model_articulated/visual/link_0.STL"/>
      </geometry>
      <material name="green">
        <color rgba="0 1 0 1"/>
      </material>
    </visual>
    <collision>
      <origin rpy="0 3.1416 -1.57" xyz="-0.0455 0.0414 0.036"/>
      <geometry>
        <mesh filename="package://robotiq_s_model_visualization/meshes/s-model_articulated/collision/link_0.STL"/>
      </geometry>
      <material name="yellow">
        <color rgba="0 1 1 1"/>
      </material>
    </collision>
    <inertial>
      <origin rpy="0 0 0" xyz="0 0 0"/>
      <mass value="0.05"/>
      <inertia ixx="0.01" ixy="-0.00002" ixz="0.00001" iyy="0.0008" iyz="0" izz="0.001"/>
    </inertial>
  </link>
  <link name="finger_2_link_1">
    <visual>
      <origin rpy="0 0 -0.52" xyz="0.050 -.028 0"/>
      <geometry>
        <mesh filename="package://robotiq_s_model_visualization/meshes/s-model_articulated/visual/link_1.STL"/>
      </geometry>
      <material name="green"/>
    </visual>
    <collision>
      <origin rpy="0 0 -0.52" xyz="0.050 -.028 0"/>
      <geometry>
        <mesh filename="package://robotiq_s_model_visualization/meshes/s-model_articulated/collision/link_1.STL"/>
      </geometry>
      <material name="yellow"/>
    </collision>
    <inertial>
      <origin rpy="0 0 0" xyz="0 0 0"/>
      <mass value="0.15"/>
      <inertia ixx="0.001859" ixy="-0.000376" ixz="0.000028" iyy="0.012756" iyz="0" izz="0.0024"/>
    </inertial>
  </link>
  <link name="finger_2_link_2">
    <!--
			NOTE: This link has an offset in the z-direction based on the models that were
			used to generate grap-it poses.  With the offset below the model appears visually
			correct, but it is suspect.
			-->
    <visual>
      <origin rpy="0 0 0" xyz="0.039 0 0.0075"/>
      <geometry>
        <mesh filename="package://robotiq_s_model_visualization/meshes/s-model_articulated/visual/link_2.STL"/>
      </geometry>
      <material name="green"/>
    </visual>
    <collision>
      <origin rpy="0 0 0" xyz="0.039 0 0.0075"/>
      <geometry>
        <mesh filename="package://robotiq_s_model_visualization/meshes/s-model_articulated/collision/link_2.STL"/>
      </geometry>
      <material name="yellow"/>
    </collision>
    <inertial>
      <origin rpy="0 0 0" xyz="0 0 0"/>
      <mass value="0.15"/>
      <inertia ixx="0.001859" ixy="-0.000376" ixz="0.000028" iyy="0.012756" iyz="0" izz="0.0024"/>
    </inertial>
  </link>
  <link name="finger_2_link_3">
    <visual>
      <origin rpy="0 0 0.52" xyz="0 0 0"/>
      <geometry>
        <mesh filename="package://robotiq_s_model_visualization/meshes/s-model_articulated/visual/link_3.STL"/>
      </geometry>
      <material name="green"/>
    </visual>
    <collision>
      <origin rpy="0 0 0.52" xyz="0 0 0"/>
      <geometry>
        <mesh filename="package://robotiq_s_model_visualization/meshes/s-model_articulated/collision/link_3.STL"/>
      </geometry>
      <material name="yellow"/>
    </collision>
    <inertial>
      <origin rpy="0 0 0" xyz="0 0 0"/>
      <mass value="0.05"/>
      <inertia ixx="0.001239" ixy="-0.000251" ixz="0.000019" iyy="0.00085" iyz="0" izz="0.001632"/>
    </inertial>
  </link>
  <joint name="finger_2_joint_1" type="revolute">
    <parent link="finger_2_link_0"/>
    <child link="finger_2_link_1"/>
    <axis xyz="0 0 1"/>
    <origin rpy="0 0 0" xyz="0.020 0 0"/>
    <limit effort="100" lower="0" upper="3.1416" velocity="100"/>
  </joint>
  <joint name="finger_2_joint_2" type="revolute">
    <parent link="finger_2_link_1"/>
    <child link="finger_2_link_2"/>
    <axis xyz="0 0 1"/>
    <origin rpy="0 0 -0.52" xyz="0.050 -.028 0"/>
    <limit effort="100" lower="0" upper="3.1416" velocity="100"/>
  </joint>
  <joint name="finger_2_joint_3" type="revolute">
    <parent link="finger_2_link_2"/>
    <child link="finger_2_link_3"/>
    <axis xyz="0 0 1"/>
    <origin rpy="0 0 0" xyz="0.039 0 0"/>
    <limit effort="100" lower="0" upper="3.1416" velocity="100"/>
  </joint>
  <link name="finger_middle_link_0">
    <visual>
      <origin rpy="0 0 0" xyz="0.020 0 0"/>
      <geometry>
        <mesh filename="package://robotiq_s_model_visualization/meshes/s-model_articulated/visual/link_0.STL"/>
      </geometry>
      <material name="green">
        <color rgba="0 1 0 1"/>
      </material>
    </visual>
    <collision>
      <origin rpy="0 3.1416 -1.57" xyz="-0.0455 0.0414 0.036"/>
      <geometry>
        <mesh filename="package://robotiq_s_model_visualization/meshes/s-model_articulated/collision/link_0.STL"/>
      </geometry>
      <material name="yellow">
        <color rgba="0 1 1 1"/>
      </material>
    </collision>
    <inertial>
      <origin rpy="0 0 0" xyz="0 0 0"/>
      <mass value="0.05"/>
      <inertia ixx="0.01" ixy="-0.00002" ixz="0.00001" iyy="0.0008" iyz="0" izz="0.001"/>
    </inertial>
  </link>
  <link name="finger_middle_link_1">
    <visual>
      <origin rpy="0 0 -0.52" xyz="0.050 -.028 0"/>
      <geometry>
        <mesh filename="package://robotiq_s_model_visualization/meshes/s-model_articulated/visual/link_1.STL"/>
      </geometry>
      <material name="green"/>
    </visual>
    <collision>
      <origin rpy="0 0 -0.52" xyz="0.050 -.028 0"/>
      <geometry>
        <mesh filename="package://robotiq_s_model_visualization/meshes/s-model_articulated/collision/link_1.STL"/>
      </geometry>
      <material name="yellow"/>
    </collision>
    <inertial>
      <origin rpy="0 0 0" xyz="0 0 0"/>
      <mass value="0.15"/>
      <inertia ixx="0.001859" ixy="-0.000376" ixz="0.000028" iyy="0.012756" iyz="0" izz="0.0024"/>
    </inertial>
  </link>
  <link name="finger_middle_link_2">
    <!--
			NOTE: This link has an offset in the z-direction based on the models that were
			used to generate grap-it poses.  With the offset below the model appears visually
			correct, but it is suspect.
			-->
    <visual>
      <origin rpy="0 0 0" xyz="0.039 0 0.0075"/>
      <geometry>
        <mesh filename="package://robotiq_s_model_visualization/meshes/s-model_articulated/visual/link_2.STL"/>
      </geometry>
      <material name="green"/>
    </visual>
    <collision>
      <origin rpy="0 0 0" xyz="0.039 0 0.0075"/>
      <geometry>
        <mesh filename="package://robotiq_s_model_visualization/meshes/s-model_articulated/collision/link_2.STL"/>
      </geometry>
      <material name="yellow"/>
    </collision>
    <inertial>
      <origin rpy="0 0 0" xyz="0 0 0"/>
      <mass value="0.15"/>
      <inertia ixx="0.001859" ixy="-0.000376" ixz="0.000028" iyy="0.012756" iyz="0" izz="0.0024"/>
    </inertial>
  </link>
  <link name="finger_middle_link_3">
    <visual>
      <origin rpy="0 0 0.52" xyz="0 0 0"/>
      <geometry>
        <mesh filename="package://robotiq_s_model_visualization/meshes/s-model_articulated/visual/link_3.STL"/>
      </geometry>
      <material name="green"/>
    </visual>
    <collision>
      <origin rpy="0 0 0.52" xyz="0 0 0"/>
      <geometry>
        <mesh filename="package://robotiq_s_model_visualization/meshes/s-model_articulated/collision/link_3.STL"/>
      </geometry>
      <material name="yellow"/>
    </collision>
    <inertial>
      <origin rpy="0 0 0" xyz="0 0 0"/>
      <mass value="0.05"/>
      <inertia ixx="0.001239" ixy="-0.000251" ixz="0.000019" iyy="0.00085" iyz="0" izz="0.001632"/>
    </inertial>
  </link>
  <joint name="finger_middle_joint_1" type="revolute">
    <parent link="finger_middle_link_0"/>
    <child link="finger_middle_link_1"/>
    <axis xyz="0 0 1"/>
    <origin rpy="0 0 0" xyz="0.020 0 0"/>
    <limit effort="100" lower="0" upper="3.1416" velocity="100"/>
  </joint>
  <joint name="finger_middle_joint_2" type="revolute">
    <parent link="finger_middle_link_1"/>
    <child link="finger_middle_link_2"/>
    <axis xyz="0 0 1"/>
    <origin rpy="0 0 -0.52" xyz="0.050 -.028 0"/>
    <limit effort="100" lower="0" upper="3.1416" velocity="100"/>
  </joint>
  <joint name="finger_middle_joint_3" type="revolute">
    <parent link="finger_middle_link_2"/>
    <child link="finger_middle_link_3"/>
    <axis xyz="0 0 1"/>
    <origin rpy="0 0 0" xyz="0.039 0 0"/>
    <limit effort="100" lower="0" upper="3.1416" velocity="100"/>
  </joint>
  <link name="palm">
    <visual>
      <geometry>
        <mesh filename="package://robotiq_s_model_visualization/meshes/s-model_articulated/visual/palm.STL"/>
      </geometry>
      <material name="green">
        <color rgba="0 1 0 1"/>
      </material>
    </visual>
    <collision>
      <geometry>
        <mesh filename="package://robotiq_s_model_visualization/meshes/s-model_articulated/collision/palm.STL"/>
      </geometry>
      <material name="yellow">
        <color rgba="0 1 1 1"/>
      </material>
    </collision>
  </link>
  <inertial>
    <origin rpy="0 0 0" xyz="0 0 0"/>
    <mass value="1.3"/>
    <inertia ixx="0.006012" ixy="0.000079" ixz="-0.00024" iyy="0.012892" iyz="0" izz="0.002435"/>
  </inertial>
  <joint name="palm_finger_1_joint" type="revolute">
    <parent link="palm"/>
    <child link="finger_1_link_0"/>
    <axis xyz="0 1 0"/>
    <origin rpy="0 3.1416 -1.57" xyz="-0.0455 0.0214 0.036"/>
    <limit effort="100" lower="-0.16" upper="0.25" velocity="100"/>
  </joint>
  <joint name="palm_finger_2_joint" type="revolute">
    <parent link="palm"/>
    <child link="finger_2_link_0"/>
    <axis xyz="0 1 0"/>
    <origin rpy="0 3.1416 -1.57" xyz="-0.0455 0.0214 -0.036"/>
    <limit effort="100" lower="-0.25" upper="0.16" velocity="100"/>
  </joint>
  <joint name="palm_finger_middle_joint" type="fixed">
    <parent link="palm"/>
    <child link="finger_middle_link_0"/>
    <axis xyz="0 0 1"/>
    <origin rpy="0 0 1.57" xyz="0.0455 0.0214 0"/>
  </joint>
  <gazebo reference="palm">
    <material>Gazebo/FlatBlack</material>
    <turnGravityOff>false</turnGravityOff>
  </gazebo>
  <!-- Used for fixing robot to Gazebo 'base_link' -->
  <link name="world"/>
  <joint name="anchor" type="fixed">
    <origin rpy="0 0 0" xyz="0 0 0.001"/>
    <parent link="world"/>
    <child link="base_link"/>
  </joint>
  <!-- Used for fixing Robotiq to the FT sensor -->
  <joint name="robotiq_anchor" type="fixed">
    <origin rpy="0 0 0" xyz="0 54e-3 0"/>
    <parent link="ft_end_effector"/>
    <child link="palm"/>
  </joint>
  <!-- ros_control plugin -->
  <gazebo>
    <plugin filename="libgazebo_ros_control.so" name="ros_control">
      <robotNamespace>/grips_robotiq</robotNamespace>
    </plugin>
  </gazebo>
</robot>

