<?xml version="1.0" ?>
<!-- =================================================================================== -->
<!-- |    This document was autogenerated by xacro from /home/fsuarez6/catkin_ws/src/grips/grips_description/robots/grips.xacro | -->
<!-- |    EDITING THIS FILE BY HAND IS NOT RECOMMENDED                                 | -->
<!-- =================================================================================== -->
<robot name="grips" xmlns:xacro="http://www.ros.org/wiki/xacro">
  <!-- Import common macros-->
  <!-- Import materials for rviz-->
  <material name="black">
    <color rgba="0.0 0.0 0.0 1.0"/>
  </material>
  <material name="blue">
    <color rgba="0.0 0.0 0.8 1.0"/>
  </material>
  <material name="green">
    <color rgba="0.0 0.8 0.0 1.0"/>
  </material>
  <material name="grey">
    <color rgba="0.2 0.2 0.2 1.0"/>
  </material>
  <material name="orange">
    <color rgba="1.0 0.423529411765 0.0392156862745 1.0"/>
  </material>
  <material name="brown">
    <color rgba="0.870588235294 0.811764705882 0.764705882353 1.0"/>
  </material>
  <material name="red">
    <color rgba="0.8 0.0 0.0 1.0"/>
  </material>
  <material name="white">
    <color rgba="1.0 1.0 1.0 1.0"/>
  </material>
  <material name="metal_seamed">
    <color rgba="0.4627450980392157 0.4666666666666667 0.4509803921568628 1.0"/>
  </material>
  <!-- Import robot without gripper -->
  <gazebo reference="base_link">
    <material>Telerobcar/MetalSeamed</material>
    <selfCollide>false</selfCollide>
  </gazebo>
  <gazebo reference="manifold_link">
    <material>Telerobcar/MetalSeamed</material>
    <selfCollide>false</selfCollide>
  </gazebo>
  <gazebo reference="upper_arm_link">
    <material>Telerobcar/MetalSeamed</material>
    <selfCollide>false</selfCollide>
  </gazebo>
  <gazebo reference="elbow_pivot_link">
    <material>Telerobcar/MetalSeamed</material>
    <selfCollide>false</selfCollide>
  </gazebo>
  <gazebo reference="coupling_link">
    <material>Telerobcar/MetalSeamed</material>
    <selfCollide>false</selfCollide>
  </gazebo>
  <gazebo reference="forearm_link">
    <material>Telerobcar/MetalSeamed</material>
    <selfCollide>false</selfCollide>
  </gazebo>
  <gazebo reference="pitch_link">
    <material>Telerobcar/MetalSeamed</material>
    <selfCollide>false</selfCollide>
  </gazebo>
  <gazebo reference="yaw_link">
    <material>Telerobcar/MetalSeamed</material>
    <selfCollide>false</selfCollide>
  </gazebo>
  <gazebo reference="camera_link">
    <material>Gazebo/FlatBlack</material>
    <selfCollide>false</selfCollide>
    <sensor name="camera1" type="camera">
      <update_rate>30.0</update_rate>
      <camera name="head">
        <horizontal_fov>1.3962634</horizontal_fov>
        <image>
          <width>800</width>
          <height>800</height>
          <format>R8G8B8</format>
        </image>
        <clip>
          <near>0.02</near>
          <far>300</far>
        </clip>
      </camera>
      <plugin filename="libgazebo_ros_camera.so" name="camera_controller">
        <alwaysOn>true</alwaysOn>
        <updateRate>0.0</updateRate>
        <cameraName>camera</cameraName>
        <imageTopicName>image_raw</imageTopicName>
        <cameraInfoTopicName>camera_info</cameraInfoTopicName>
        <frameName>camera_link</frameName>
        <hackBaseline>0.07</hackBaseline>
        <distortionK1>0.0</distortionK1>
        <distortionK2>0.0</distortionK2>
        <distortionK3>0.0</distortionK3>
        <distortionT1>0.0</distortionT1>
        <distortionT2>0.0</distortionT2>
      </plugin>
    </sensor>
  </gazebo>
  <link name="base_link">
    <visual>
      <geometry>
        <mesh filename="package://grips_description/meshes/base/base.dae"/>
      </geometry>
      <material name="black"/>
    </visual>
    <collision>
      <geometry>
        <mesh filename="package://grips_description/meshes/base/base_collision.dae"/>
      </geometry>
    </collision>
    <inertial>
      <origin rpy="0 0 0" xyz="0 0 7e-3"/>
      <mass value="1.208"/>
      <inertia ixx="0.003" ixy="0.0" ixz="0.0" iyy="0.003" iyz="0.0" izz="0.006"/>
    </inertial>
  </link>
  <link name="manifold_link">
    <visual>
      <geometry>
        <mesh filename="package://grips_description/meshes/manifold/manifold.dae"/>
      </geometry>
      <material name="blue"/>
    </visual>
    <collision>
      <geometry>
        <mesh filename="package://grips_description/meshes/manifold/manifold_collision.dae"/>
      </geometry>
    </collision>
    <inertial>
      <origin rpy="0 0 0" xyz="0 2e-3 0.21"/>
      <mass value="41.111"/>
      <inertia ixx="0.549" ixy="-9.556e-5" ixz="-5.871e-5" iyy="0.855" iyz="2e-3" izz="0.605"/>
    </inertial>
  </link>
  <link name="upper_arm_link">
    <visual>
      <geometry>
        <mesh filename="package://grips_description/meshes/upper_arm/upper_arm.dae"/>
      </geometry>
      <material name="black"/>
    </visual>
    <collision>
      <geometry>
        <mesh filename="package://grips_description/meshes/upper_arm/upper_arm_collision.dae"/>
      </geometry>
    </collision>
    <inertial>
      <origin rpy="0 0 0" xyz="0 5e-3 0.227"/>
      <mass value="3.592"/>
      <inertia ixx="0.103" ixy="0" ixz="0" iyy="0.106" iyz="0.004" izz="0.013"/>
    </inertial>
  </link>
  <link name="elbow_pivot_link">
    <visual>
      <geometry>
        <mesh filename="package://grips_description/meshes/linkage/elbow_pivot.dae"/>
      </geometry>
      <material name="black"/>
    </visual>
    <collision>
      <geometry>
        <mesh filename="package://grips_description/meshes/linkage/elbow_pivot.dae"/>
      </geometry>
    </collision>
    <inertial>
      <origin rpy="0 0 0" xyz="-3.6e-10 80.686e-3 -6.33e-5"/>
      <mass value="0.72"/>
      <inertia ixx="0.002" ixy="-3.231e-27" ixz="0" iyy="3.397e-4" iyz="-1.919e-5" izz="0.002"/>
    </inertial>
  </link>
  <link name="coupling_link">
    <visual>
      <geometry>
        <mesh filename="package://grips_description/meshes/linkage/coupling.dae"/>
      </geometry>
      <material name="black"/>
    </visual>
    <collision>
      <geometry>
        <mesh filename="package://grips_description/meshes/linkage/coupling.dae"/>
      </geometry>
    </collision>
    <inertial>
      <origin rpy="0 0 0" xyz="0 0 -0.26035"/>
      <mass value="0.446"/>
      <inertia ixx="0.011" ixy="-3.231e-27" ixz="0" iyy="0.011" iyz="0" izz="2.102e-5"/>
    </inertial>
  </link>
  <link name="forearm_link">
    <visual>
      <geometry>
        <mesh filename="package://grips_description/meshes/forearm/forearm.dae"/>
      </geometry>
      <material name="black"/>
    </visual>
    <collision>
      <geometry>
        <mesh filename="package://grips_description/meshes/forearm/forearm_collision.dae"/>
      </geometry>
    </collision>
    <inertial>
      <origin rpy="0 0 0" xyz="0 0.155337 0.012119"/>
      <mass value="4.935"/>
      <inertia ixx="0.073" ixy="0" ixz="0" iyy="0.009" iyz="0.004" izz="0.073"/>
    </inertial>
  </link>
  <link name="pitch_link">
    <visual>
      <geometry>
        <mesh filename="package://grips_description/meshes/pitch/pitch.dae"/>
      </geometry>
      <material name="black"/>
    </visual>
    <collision>
      <geometry>
        <mesh filename="package://grips_description/meshes/pitch/pitch_collision.dae"/>
      </geometry>
    </collision>
    <inertial>
      <origin rpy="0 0 0" xyz="0 0.065 0"/>
      <mass value="0.679"/>
      <inertia ixx="0.003" ixy="0" ixz="0" iyy="0.002" iyz="0.004" izz="0.002"/>
    </inertial>
  </link>
  <link name="yaw_link">
    <visual>
      <geometry>
        <mesh filename="package://grips_description/meshes/yaw/yaw.dae"/>
      </geometry>
      <material name="black"/>
    </visual>
    <collision>
      <geometry>
        <mesh filename="package://grips_description/meshes/yaw/yaw_collision.dae"/>
      </geometry>
    </collision>
    <inertial>
      <origin rpy="0 0 0" xyz="-1e-3 95.791e-3 18.273e-3"/>
      <mass value="4.689"/>
      <inertia ixx="0.027" ixy="1.597e-4" ixz="-2.174e-4" iyy="0.009" iyz="-0.003" izz="0.026"/>
    </inertial>
  </link>
  <link name="end_effector"/>
  <link name="camera_link">
    <visual>
      <geometry>
        <mesh filename="package://grips_description/meshes/camera/camera.dae"/>
      </geometry>
      <material name="black"/>
    </visual>
    <collision>
      <geometry>
        <mesh filename="package://grips_description/meshes/camera/camera_collision.dae"/>
      </geometry>
    </collision>
    <inertial>
      <origin rpy="0 0 0" xyz="0.077 0.007 0.002"/>
      <mass value="0.869"/>
      <inertia ixx="0.001" ixy="-1.561e-4" ixz="-5.859e-5" iyy="0.002" iyz="3.295e-5" izz="0.002"/>
    </inertial>
  </link>
  <joint name="SA" type="revolute">
    <child link="manifold_link"/>
    <parent link="base_link"/>
    <axis xyz="0 0 1"/>
    <origin rpy="0 0 0" xyz="0 0 15.24e-3"/>
    <limit effort="200" lower="-1.57079632679" upper="1.57079632679" velocity="15"/>
    <dynamics damping="5"/>
  </joint>
  <joint name="SE" type="revolute">
    <child link="upper_arm_link"/>
    <parent link="manifold_link"/>
    <axis xyz="1 0 0"/>
    <origin rpy="0 0 0" xyz="0 0 0.33812"/>
    <limit effort="200" lower="-1.57079632679" upper="0.523598775598" velocity="15"/>
    <dynamics damping="5" friction="10"/>
  </joint>
  <joint name="linkage_tr" type="revolute">
    <child link="forearm_link"/>
    <parent link="upper_arm_link"/>
    <axis xyz="1 0 0"/>
    <origin rpy="0 0 0" xyz="0 -9.82e-3 0.52167"/>
    <limit effort="200" lower="-1.28" upper="1.0471975512" velocity="15"/>
    <dynamics damping="10"/>
  </joint>
  <joint name="WP" type="revolute">
    <child link="pitch_link"/>
    <parent link="forearm_link"/>
    <axis xyz="1 0 0"/>
    <origin rpy="0 0 0" xyz="0 0.26109 7.5e-3"/>
    <limit effort="200" lower="-1.1" upper="0.581" velocity="15"/>
    <dynamics damping="5"/>
  </joint>
  <joint name="WY" type="revolute">
    <child link="yaw_link"/>
    <parent link="pitch_link"/>
    <axis xyz="0 0 1"/>
    <origin rpy="0 0 0" xyz="0 0.13322 0"/>
    <limit effort="200" lower="-1.01" upper="0.675" velocity="15"/>
    <dynamics damping="5"/>
  </joint>
  <joint name="WR" type="continuous">
    <child link="end_effector"/>
    <parent link="yaw_link"/>
    <axis xyz="0 1 0"/>
    <origin rpy="0 0 0" xyz="-0.787e-3 0.190892 0.051331"/>
    <limit effort="200" velocity="200"/>
    <dynamics damping="0.5"/>
  </joint>
  <joint name="camera_joint" type="fixed">
    <child link="camera_link"/>
    <parent link="yaw_link"/>
    <axis xyz="0 1 0"/>
    <origin rpy="0 0.523598775598 1.57079632679" xyz="0 0.095446 0.25"/>
  </joint>
  <joint name="linkage_tl" type="continuous">
    <child link="coupling_link"/>
    <parent link="forearm_link"/>
    <axis xyz="1 0 0"/>
    <origin rpy="0.019320795 0 0" xyz="0 -0.123444 0.029845"/>
    <limit effort="200" velocity="15"/>
    <dynamics damping="0.5" friction="0.5"/>
  </joint>
  <joint name="linkage_bl" type="continuous">
    <child link="elbow_pivot_link"/>
    <parent link="coupling_link"/>
    <axis xyz="1 0 0"/>
    <origin rpy="-0.24521876 0 0" xyz="0 0 -0.5207"/>
    <limit effort="200" velocity="15"/>
    <dynamics damping="0.5" friction="0.5"/>
  </joint>
  <transmission name="SA_tran">
    <type>transmission_interface/SimpleTransmission</type>
    <joint name="SA"/>
    <actuator name="SA_motor">
      <hardwareInterface>EffortJointInterface</hardwareInterface>
      <mechanicalReduction>1</mechanicalReduction>
    </actuator>
  </transmission>
  <transmission name="SE_tran">
    <type>transmission_interface/SimpleTransmission</type>
    <joint name="SE"/>
    <actuator name="SE_motor">
      <hardwareInterface>EffortJointInterface</hardwareInterface>
      <mechanicalReduction>1</mechanicalReduction>
    </actuator>
  </transmission>
  <transmission name="WP_tran">
    <type>transmission_interface/SimpleTransmission</type>
    <joint name="WP"/>
    <actuator name="WP_motor">
      <hardwareInterface>EffortJointInterface</hardwareInterface>
      <mechanicalReduction>1</mechanicalReduction>
    </actuator>
  </transmission>
  <transmission name="WY_tran">
    <type>transmission_interface/SimpleTransmission</type>
    <joint name="WY"/>
    <actuator name="WY_motor">
      <hardwareInterface>EffortJointInterface</hardwareInterface>
      <mechanicalReduction>1</mechanicalReduction>
    </actuator>
  </transmission>
  <transmission name="WR_tran">
    <type>transmission_interface/SimpleTransmission</type>
    <joint name="WR"/>
    <actuator name="WR_motor">
      <hardwareInterface>EffortJointInterface</hardwareInterface>
      <mechanicalReduction>1</mechanicalReduction>
    </actuator>
  </transmission>
  <transmission name="linkage_tr_tran">
    <type>transmission_interface/SimpleTransmission</type>
    <joint name="linkage_tr"/>
    <actuator name="linkage_tr_motor">
      <hardwareInterface>EffortJointInterface</hardwareInterface>
      <mechanicalReduction>1</mechanicalReduction>
    </actuator>
  </transmission>
  <transmission name="linkage_tl_tran">
    <type>transmission_interface/SimpleTransmission</type>
    <joint name="linkage_tl"/>
    <actuator name="linkage_tl_motor">
      <hardwareInterface>EffortJointInterface</hardwareInterface>
      <mechanicalReduction>1</mechanicalReduction>
    </actuator>
  </transmission>
  <transmission name="linkage_bl_tran">
    <type>transmission_interface/SimpleTransmission</type>
    <joint name="linkage_bl"/>
    <actuator name="linkage_bl_motor">
      <hardwareInterface>EffortJointInterface</hardwareInterface>
      <mechanicalReduction>1</mechanicalReduction>
    </actuator>
  </transmission>
  <!-- Used for fixing robot to Gazebo 'base_link' -->
  <link name="world"/>
  <joint name="anchor" type="fixed">
    <origin rpy="0 0 0" xyz="0 0 0.001"/>
    <parent link="world"/>
    <child link="base_link"/>
  </joint>
</robot>
